{
  "nbformat": 4,
  "nbformat_minor": 0,
  "metadata": {
    "colab": {
      "provenance": []
    },
    "kernelspec": {
      "name": "python3",
      "display_name": "Python 3"
    },
    "language_info": {
      "name": "python"
    }
  },
  "cells": [
    {
      "cell_type": "code",
      "source": [],
      "metadata": {
        "id": "Z9sYcDE-qV7z"
      },
      "execution_count": null,
      "outputs": []
    },
    {
      "cell_type": "markdown",
      "source": [
        "# 1.) Import an asset price from Yahoo Finance"
      ],
      "metadata": {
        "id": "6dJuZDx9qWeM"
      }
    },
    {
      "cell_type": "code",
      "source": [
        "pip install yfinance"
      ],
      "metadata": {
        "colab": {
          "base_uri": "https://localhost:8080/"
        },
        "id": "QxUUnTVTrx3m",
        "outputId": "74463726-a600-4056-8c8d-c99ce8ebead6"
      },
      "execution_count": null,
      "outputs": [
        {
          "output_type": "stream",
          "name": "stdout",
          "text": [
            "Looking in indexes: https://pypi.org/simple, https://us-python.pkg.dev/colab-wheels/public/simple/\n",
            "Requirement already satisfied: yfinance in /usr/local/lib/python3.8/dist-packages (0.2.12)\n",
            "Requirement already satisfied: cryptography>=3.3.2 in /usr/local/lib/python3.8/dist-packages (from yfinance) (39.0.1)\n",
            "Requirement already satisfied: pandas>=1.3.0 in /usr/local/lib/python3.8/dist-packages (from yfinance) (1.3.5)\n",
            "Requirement already satisfied: lxml>=4.9.1 in /usr/local/lib/python3.8/dist-packages (from yfinance) (4.9.2)\n",
            "Requirement already satisfied: requests>=2.26 in /usr/local/lib/python3.8/dist-packages (from yfinance) (2.28.2)\n",
            "Requirement already satisfied: numpy>=1.16.5 in /usr/local/lib/python3.8/dist-packages (from yfinance) (1.22.4)\n",
            "Requirement already satisfied: appdirs>=1.4.4 in /usr/local/lib/python3.8/dist-packages (from yfinance) (1.4.4)\n",
            "Requirement already satisfied: frozendict>=2.3.4 in /usr/local/lib/python3.8/dist-packages (from yfinance) (2.3.5)\n",
            "Requirement already satisfied: multitasking>=0.0.7 in /usr/local/lib/python3.8/dist-packages (from yfinance) (0.0.11)\n",
            "Requirement already satisfied: pytz>=2022.5 in /usr/local/lib/python3.8/dist-packages (from yfinance) (2022.7.1)\n",
            "Requirement already satisfied: html5lib>=1.1 in /usr/local/lib/python3.8/dist-packages (from yfinance) (1.1)\n",
            "Requirement already satisfied: beautifulsoup4>=4.11.1 in /usr/local/lib/python3.8/dist-packages (from yfinance) (4.11.2)\n",
            "Requirement already satisfied: soupsieve>1.2 in /usr/local/lib/python3.8/dist-packages (from beautifulsoup4>=4.11.1->yfinance) (2.4)\n",
            "Requirement already satisfied: cffi>=1.12 in /usr/local/lib/python3.8/dist-packages (from cryptography>=3.3.2->yfinance) (1.15.1)\n",
            "Requirement already satisfied: webencodings in /usr/local/lib/python3.8/dist-packages (from html5lib>=1.1->yfinance) (0.5.1)\n",
            "Requirement already satisfied: six>=1.9 in /usr/local/lib/python3.8/dist-packages (from html5lib>=1.1->yfinance) (1.15.0)\n",
            "Requirement already satisfied: python-dateutil>=2.7.3 in /usr/local/lib/python3.8/dist-packages (from pandas>=1.3.0->yfinance) (2.8.2)\n",
            "Requirement already satisfied: charset-normalizer<4,>=2 in /usr/local/lib/python3.8/dist-packages (from requests>=2.26->yfinance) (3.0.1)\n",
            "Requirement already satisfied: idna<4,>=2.5 in /usr/local/lib/python3.8/dist-packages (from requests>=2.26->yfinance) (2.10)\n",
            "Requirement already satisfied: urllib3<1.27,>=1.21.1 in /usr/local/lib/python3.8/dist-packages (from requests>=2.26->yfinance) (1.24.3)\n",
            "Requirement already satisfied: certifi>=2017.4.17 in /usr/local/lib/python3.8/dist-packages (from requests>=2.26->yfinance) (2022.12.7)\n",
            "Requirement already satisfied: pycparser in /usr/local/lib/python3.8/dist-packages (from cffi>=1.12->cryptography>=3.3.2->yfinance) (2.21)\n"
          ]
        }
      ]
    },
    {
      "cell_type": "code",
      "execution_count": null,
      "metadata": {
        "colab": {
          "base_uri": "https://localhost:8080/"
        },
        "id": "Y3bcwJb4rp93",
        "outputId": "3f5d4c73-af3d-4e72-c049-c1f28124dca6"
      },
      "outputs": [
        {
          "output_type": "stream",
          "name": "stdout",
          "text": [
            "\r[*********************100%***********************]  1 of 1 completed\n"
          ]
        }
      ],
      "source": [
        "import yfinance as yf\n",
        "import numpy as np\n",
        "import pandas as pd\n",
        "from sklearn.preprocessing import MinMaxScaler\n",
        "from tensorflow.keras.models import Sequential\n",
        "from tensorflow.keras.layers import Dense, LSTM, Dropout\n",
        "\n",
        "\n",
        "########################################\n",
        "####Pick your ticker and time period####\n",
        "########################################\n",
        "#### Kellog starting on Aug 1, 1985 ####\n",
        "\n",
        "stock_data = yf.download(\"K\", start=\"1985-08-01\", end=\"2022-02-21\")\n",
        "\n",
        "\n",
        "\n",
        "# Preprocess data\n",
        "scaled_data = np.array(stock_data[\"Close\"].pct_change().dropna()).reshape(-1,1)\n",
        "\n",
        "\n",
        "# Split data into training and test sets\n",
        "training_data_len = int(len(scaled_data) * 0.8)\n",
        "train_data = scaled_data[0:training_data_len, :]"
      ]
    },
    {
      "cell_type": "markdown",
      "source": [
        "# 2.) Create your x_train/y_train data so that your RNN uses percentage change data to make a binary forecast where the stock moves up or down the next day\n",
        "# Build an RNN Architecture accordingly"
      ],
      "metadata": {
        "id": "foHoGy9hq3_o"
      }
    },
    {
      "cell_type": "code",
      "source": [
        "# Create x_train and y_train data\n",
        "x_train = []\n",
        "y_train = []\n",
        "input_size = 10\n",
        "\n",
        "for i in range(input_size, len(train_data)):\n",
        "    x_train.append(train_data[i-input_size:i, 0])\n",
        "    if train_data[i, 0] > 0:\n",
        "        y_train.append(1)\n",
        "    else:\n",
        "        y_train.append(0)\n",
        "\n",
        "# Convert to numpy arrays and reshape for LSTM input\n",
        "x_train = np.array(x_train)\n",
        "y_train = np.array(y_train)\n",
        "print(\"Shapes before reshaping:\", x_train.shape, y_train.shape)\n",
        "x_train = np.reshape(x_train, (x_train.shape[0], x_train.shape[1], 1))\n",
        "print(\"Shapes after reshaping:\", x_train.shape, y_train.shape)\n",
        "\n",
        "# Build an RNN Architecture\n",
        "model = Sequential()\n",
        "model.add(LSTM(50, return_sequences=True, input_shape=(x_train.shape[1], 1)))\n",
        "model.add(LSTM(50, return_sequences=False))\n",
        "model.add(Dense(25))\n",
        "model.add(Dense(1, activation='sigmoid'))\n",
        "model.compile(optimizer='adam', loss='mean_squared_error', metrics=['accuracy'])\n",
        "\n",
        "# Train the model\n",
        "model.fit(x_train, y_train, batch_size=1, epochs=3)\n"
      ],
      "metadata": {
        "id": "5qGFB5HfqcVd",
        "colab": {
          "base_uri": "https://localhost:8080/"
        },
        "outputId": "44c8d6ef-8bfe-4c1f-d8f2-6eed6fde13e5"
      },
      "execution_count": null,
      "outputs": [
        {
          "output_type": "stream",
          "name": "stdout",
          "text": [
            "Shapes before reshaping: (7360, 10) (7360,)\n",
            "Shapes after reshaping: (7360, 10, 1) (7360,)\n",
            "Epoch 1/3\n",
            "7360/7360 [==============================] - 62s 7ms/step - loss: 0.2504 - accuracy: 0.5031\n",
            "Epoch 2/3\n",
            "7360/7360 [==============================] - 53s 7ms/step - loss: 0.2501 - accuracy: 0.5053\n",
            "Epoch 3/3\n",
            "7360/7360 [==============================] - 51s 7ms/step - loss: 0.2499 - accuracy: 0.5111\n"
          ]
        },
        {
          "output_type": "execute_result",
          "data": {
            "text/plain": [
              "<keras.callbacks.History at 0x7f55446aa970>"
            ]
          },
          "metadata": {},
          "execution_count": 69
        }
      ]
    },
    {
      "cell_type": "code",
      "source": [
        "#Epoch 1, 2, and 3 each recorded accuracies around ~50%"
      ],
      "metadata": {
        "id": "p3BlSFA8Na77"
      },
      "execution_count": null,
      "outputs": []
    },
    {
      "cell_type": "code",
      "source": [
        "import pandas as pd\n",
        "\n",
        "# Compute the percentage change in the asset price\n",
        "pct_change_data = pd.DataFrame(scaled_data).pct_change().values[1:]\n",
        "pct_change_data"
      ],
      "metadata": {
        "colab": {
          "base_uri": "https://localhost:8080/"
        },
        "id": "olgrKcwK8qMj",
        "outputId": "b14c8de9-cd22-4977-e4de-b90f12de36b1"
      },
      "execution_count": null,
      "outputs": [
        {
          "output_type": "execute_result",
          "data": {
            "text/plain": [
              "array([[ 0.99099099],\n",
              "       [-3.22991071],\n",
              "       [ 0.58744622],\n",
              "       ...,\n",
              "       [ 0.69162056],\n",
              "       [-2.93402196],\n",
              "       [ 1.34643652]])"
            ]
          },
          "metadata": {},
          "execution_count": 71
        }
      ]
    },
    {
      "cell_type": "code",
      "source": [
        "# Compute the binary variable y\n",
        "y = (pct_change_data[:, 0] > 0).astype(int)\n",
        "y = y[1:]  # Remove the first row, which has no corresponding y value"
      ],
      "metadata": {
        "id": "2NdZ8TRN8tQD"
      },
      "execution_count": null,
      "outputs": []
    },
    {
      "cell_type": "markdown",
      "source": [
        "# 3.) Test your model and compare insample Accurracy, insample random walk assumption Accuracy, Out of sample Accuracy and out of sample random walk assumption Accuracy using a bar chart"
      ],
      "metadata": {
        "id": "yFhO9vMjsWPk"
      }
    },
    {
      "cell_type": "code",
      "source": [
        "\n",
        "test_data = scaled_data[training_data_len - input_size:, :]\n",
        "\n",
        "x_test = []\n",
        "y_test = np.array(stock_data[[\"Close\"]].pct_change().dropna())[training_data_len:, :]\n",
        "for i in range(input_size, len(test_data)):\n",
        "    x_test.append(test_data[i-input_size:i, 0])\n",
        "\n",
        "x_test = np.array(x_test)\n",
        "x_test = np.reshape(x_test, (x_test.shape[0], x_test.shape[1], 1))\n",
        "\n",
        "\n",
        "\n",
        "\n",
        "predictions = model.predict(x_test)\n",
        "\n"
      ],
      "metadata": {
        "id": "r1Xj6Ji-rwnM",
        "colab": {
          "base_uri": "https://localhost:8080/"
        },
        "outputId": "1e5977d6-51bc-4264-db30-caca4292adab"
      },
      "execution_count": null,
      "outputs": [
        {
          "output_type": "stream",
          "name": "stdout",
          "text": [
            "58/58 [==============================] - 3s 7ms/step\n"
          ]
        }
      ]
    },
    {
      "cell_type": "code",
      "source": [
        "from sklearn.preprocessing import MinMaxScaler\n",
        "\n",
        "# Create a scaler object\n",
        "scaler = MinMaxScaler(feature_range=(0, 1))\n",
        "\n",
        "# Fit the scaler to the training data\n",
        "scaler.fit(train_data)\n",
        "\n",
        "\n",
        "# Invert the scaling for the predictions and actual prices\n",
        "predictions = scaler.inverse_transform(predictions)\n",
        "y_test = scaler.inverse_transform(y_test.reshape(-1, 1))\n"
      ],
      "metadata": {
        "id": "o1IrOE0jRbA4"
      },
      "execution_count": null,
      "outputs": []
    },
    {
      "cell_type": "code",
      "source": [
        "# Random Walk\n",
        "# Did it go up yesterday? And will it go up today\n",
        "\n",
        "y_test[1:] # Actual\n",
        "y_test[:-1] # Prediction\n",
        "\n",
        "# OOS Random walk model\n",
        "y_test[1:] # Actual\n",
        "y_test[:-1] # Prediction"
      ],
      "metadata": {
        "id": "Mvo2INihZMhk",
        "colab": {
          "base_uri": "https://localhost:8080/"
        },
        "outputId": "07854b2c-cbb1-4d17-affd-1ed1c660e8a4"
      },
      "execution_count": null,
      "outputs": [
        {
          "output_type": "execute_result",
          "data": {
            "text/plain": [
              "array([[-0.2616229 ],\n",
              "       [-0.25769216],\n",
              "       [-0.26513553],\n",
              "       ...,\n",
              "       [-0.26414284],\n",
              "       [-0.26499494],\n",
              "       [-0.25888002]])"
            ]
          },
          "metadata": {},
          "execution_count": 75
        }
      ]
    },
    {
      "cell_type": "code",
      "source": [
        "#Making predictions on the test data\n",
        "\n",
        "predictions = model.predict(x_test)\n",
        "predictions = (predictions > 0.5)"
      ],
      "metadata": {
        "id": "ZP_GJ8X-Wkln",
        "colab": {
          "base_uri": "https://localhost:8080/"
        },
        "outputId": "d963180e-7481-49c1-98b1-bd2644c5ddb9"
      },
      "execution_count": null,
      "outputs": [
        {
          "output_type": "stream",
          "name": "stdout",
          "text": [
            "58/58 [==============================] - 0s 5ms/step\n"
          ]
        }
      ]
    },
    {
      "cell_type": "code",
      "source": [
        "#Calculating in-sample accuracy\n",
        "from sklearn.metrics import accuracy_score\n",
        "\n",
        "\n",
        "train_predictions = model.predict(x_train)\n",
        "train_predictions = (train_predictions > 0.5)\n",
        "in_sample_acc = accuracy_score(y_train, train_predictions)"
      ],
      "metadata": {
        "colab": {
          "base_uri": "https://localhost:8080/"
        },
        "id": "No5lGQhNSKfh",
        "outputId": "c5c2d77d-168c-478c-849d-934873acc585"
      },
      "execution_count": null,
      "outputs": [
        {
          "output_type": "stream",
          "name": "stdout",
          "text": [
            "230/230 [==============================] - 1s 5ms/step\n"
          ]
        }
      ]
    },
    {
      "cell_type": "code",
      "source": [
        "#Calculating in-sample random walk assumption accuracy\n",
        "\n",
        "y_train_rw = np.roll(y_train, 1)\n",
        "y_train_rw[0] = 0\n",
        "in_sample_rw_acc = accuracy_score(y_train, y_train_rw)"
      ],
      "metadata": {
        "id": "PS6bTft8SP1E"
      },
      "execution_count": null,
      "outputs": []
    },
    {
      "cell_type": "code",
      "source": [
        "#Calculating out-of-sample accuracy\n",
        "from sklearn.metrics import mean_squared_error\n",
        "\n",
        "\n",
        "# Make predictions on the test data\n",
        "predictions = model.predict(x_test)\n",
        "\n",
        "# Invert the scaling for the predictions and actual prices\n",
        "predictions = scaler.inverse_transform(predictions)\n",
        "y_test = scaler.inverse_transform(y_test.reshape(-1, 1))\n",
        "\n",
        "# Calculate the MSE\n",
        "mse = mean_squared_error(y_test, predictions)\n",
        "print('MSE:', mse)"
      ],
      "metadata": {
        "colab": {
          "base_uri": "https://localhost:8080/"
        },
        "id": "zwSOxQR2SZqk",
        "outputId": "a08659b7-ad43-455c-f4ba-0959937e0865"
      },
      "execution_count": null,
      "outputs": [
        {
          "output_type": "stream",
          "name": "stdout",
          "text": [
            "58/58 [==============================] - 0s 5ms/step\n",
            "MSE: 0.1345004475855685\n"
          ]
        }
      ]
    },
    {
      "cell_type": "code",
      "source": [
        "\n",
        "\n",
        "\n",
        "# Computing the out-of-sample random walk assumption accuracy using MAE and RMSE\n",
        "y_test_rw = np.roll(y_test, 1)\n",
        "y_test_rw[0] = 0\n",
        "\n",
        "mae_rw = np.mean(np.abs(y_test - y_test_rw))\n",
        "rmse_rw = np.sqrt(np.mean(np.square(y_test - y_test_rw)))\n",
        "\n",
        "print('Out-of-sample RW assumption MAE:', mae_rw)\n",
        "print('Out-of-sample RW assumption RMSE:', rmse_rw)"
      ],
      "metadata": {
        "colab": {
          "base_uri": "https://localhost:8080/"
        },
        "id": "_dKKqJXASmb8",
        "outputId": "d97a57ec-17db-48c9-bed2-dbc54a823f37"
      },
      "execution_count": null,
      "outputs": [
        {
          "output_type": "stream",
          "name": "stdout",
          "text": [
            "Out-of-sample RW assumption MAE: 0.0035754918358778007\n",
            "Out-of-sample RW assumption RMSE: 0.010337945251247524\n"
          ]
        }
      ]
    },
    {
      "cell_type": "code",
      "source": [
        "import matplotlib.pyplot as plt\n",
        "\n",
        "# in-sample accuracy\n",
        "_, in_sample_acc = model.evaluate(x_train, y_train, verbose=0)\n",
        "\n",
        "\n",
        "#  out-of-sample accuracy\n",
        "out_sample_acc = model.evaluate(x_test, y_test, verbose=0)[1]\n",
        "\n",
        "#  out-of-sample random walk assumption accuracy using MAE and RMSE\n",
        "y_test_rw = np.roll(y_test, 1)\n",
        "y_test_rw[0] = 0\n",
        "\n",
        "mae_rw_test = np.mean(np.abs(y_test - y_test_rw))\n",
        "rmse_rw_test = np.sqrt(np.mean(np.square(y_test - y_test_rw)))\n",
        "\n",
        "# Finally, a bar chart to compare the accuracies\n",
        "labels = ['In-sample accuracy', 'In-sample RW assumption MAE', 'In-sample RW assumption RMSE',\n",
        "          'Out-of-sample RW assumption MAE', 'Out-of-sample RW assumption RMSE']\n",
        "values = [in_sample_acc, in_sample_rw_acc, rmse_rw, mae_rw, rmse_rw_test]\n",
        "\n",
        "plt.figure(figsize=(30, 15))\n",
        "plt.bar(labels, values)\n",
        "plt.title('Comparison of accuracies')\n",
        "plt.ylabel('Accuracy')\n",
        "plt.show()\n"
      ],
      "metadata": {
        "colab": {
          "base_uri": "https://localhost:8080/",
          "height": 880
        },
        "id": "yEKsg--CZLSA",
        "outputId": "31c0dce7-ae99-4b8d-96f7-bc79e71add71"
      },
      "execution_count": null,
      "outputs": [
        {
          "output_type": "display_data",
          "data": {
            "text/plain": [
              "<Figure size 2160x1080 with 1 Axes>"
            ],
            "image/png": "iVBORw0KGgoAAAANSUhEUgAABr0AAANeCAYAAACvWsXCAAAAOXRFWHRTb2Z0d2FyZQBNYXRwbG90bGliIHZlcnNpb24zLjUuMywgaHR0cHM6Ly9tYXRwbG90bGliLm9yZy/NK7nSAAAACXBIWXMAAAsTAAALEwEAmpwYAABCpElEQVR4nO3debxuZV3///dHEOehAocUxRQHnEgJ1CbU6qdZoDkgOWSTWVGp6VdSM6Xha/pVK8WcU3MA53DIIRXNMRBRQCIRUVBUMBVnQT6/P9bacLPd55x9Duc+h+uc5/PxOA/2ve51r/vaa7Ovvff9utda1d0BAAAAAACAkV1hew8AAAAAAAAALivRCwAAAAAAgOGJXgAAAAAAAAxP9AIAAAAAAGB4ohcAAAAAAADDE70AAAAAAAAYnugFAACwBarqQVX1zu09jhVVdZWqenNVfaOqXru9x7M1Xd72NQAAcPlU3b29xwAAAOzEquo3kzw6yS2TfDPJiUn+trs/sD3HNZqqekiSP0lyl+6+cHuPBwAAYFtzpBcAALDdVNWjk/xDkr9Lct0kN0ry3CQHb8dhbVJV7bq9x7CGGyf5n8tr8Lqc7jMAAGAHInoBAADbRVVdK8kRSf64u9/Q3d/u7gu6+83d/dh5nStV1T9U1Rfnf/9QVVea7zuwqs6uqv9TVV+pqnOq6t5V9atV9T9V9b9V9fiF53tyVb2uqo6uqm9W1QlVdfuF+w+vqs/M932qqu6zcN/DquqDVfWsqvpqkifPyz4w31/zfV+pqvOr6qSqus3K51lVL6+qc6vqc1X1xKq6wsJ2P1BV/6+qvlZVn62qe25kn92qqo6tqq9X1SlVddC8/ClJnpTkkKr6VlX97hqP3b+qPjw/9pyqek5V7bZw/62r6l3zfvvyyr6rql2q6vEL++ZjVbVnVe1VVb0Ys+ax/d5G9tlNq+o9VfXVqjqvql5ZVddeePyeVfWGeV99taqes7ifFta75cJYT6uqByzc96vz1++bVfWFqnrMhvYnAACwYxG9AACA7eXOSa6c5I0bWecJSe6UZN8kt0+yf5InLtx/vXkbN8gUfV6Y5MFJ7pjk55P8ZVXdZGH9g5O8NsmPJ3lVkjdV1RXn+z4zP+ZaSZ6S5BVVdf2Fxx6Q5IxMR6T97apx/kqSX0hy8/nxD0jy1fm+Z8/LfirJLyZ5aJLfXrXd05LsnuRpSV5cVbV6R8zjfHOSdya5TqZTGb6yqm7R3X+V6Wi5o7v76t394tWPT/LDJI+an+fOSe6e5I/mbV8jyX8keXuSn0xysyTvnh/36CSHJvnVJNdM8jtJvrPG9teyep9Vkv87P8etkuyZ5MnzGHZJ8pYkn0uyV6av6VFr7IerJXlXpq/fdZI8MMlzq2qfeZUXJ/mD7r5Gktskec86xwoAAAxO9AIAALaXn0hy3iZOx/egJEd091e6+9xMMeohC/dfkOn6XxdkCiS7J/nH7v5md5+S5FOZYtmKj3X36+b1n5kpmN0pSbr7td39xe6+qLuPTvLpTJFtxRe7+9ndfWF3f3fVOC9Ico1M1yWr7j61u8+ZQ84Dk/zFPKYzkzxj1efwue5+YXf/MMnLklw/UyRa7U5Jrp7kqd39g+5+T6ZIdOhG9t/Fuvtj3f2RefxnJnl+pgiXJL+W5Evd/Yzu/t481o/O9/1ekid292k9+UR3f3WNp1jLpfZZd5/e3e/q7u/PX89nLoxh/0wx7LHzUX/f28B13X4tyZnd/S/zdj+e5PVJ7j/ff0GSfarqmt39te4+YZ1jBQAABid6AQAA28tXk+y+iWs9/WSmI39WfG5edvE25liUJCsh6ssL9383UyhacdbKB919UZKzV7ZXVQ+tqhPn0/99PdNRQruv9djV5gD1nCRHJvlKVb2gqq45P/6Ka3wON1i4/aWF7awcQbU45hU/meSsedwb2tYGVdXNq+otVfWlqjo/05FhK5/fnpmOdFvLxu7blEvts6q6blUdNZ928Pwkr1g1hs+t45pkN05ywMrXaf5aPSjTUX9Jct9MR6V9rqreV1V33sKxAwAAgxG9AACA7eXDSb6f5N4bWeeLmSLHihvNy7bUnisfzNfVumGSL1bVjTOdGvGwJD/R3ddOcnKm0/Gt6I1tuLv/qbvvmGSfTKc5fGyS8zIdebT6c/jCFoz9i0n2XLke2BZs65+T/HeSvbv7mkken0s+v7MynX5xLWcluekay789//eqC8uut2qd1fvs7+Zlt53H8OBVY7jRJiLoynrv6+5rL/y7enf/YZJ093HdfXCmUx++KclrNrE9AABgByF6AQAA20V3fyPTdbiOrKp7V9VVq+qKVXXPqnravNqrkzyxqvaoqt3n9V9xGZ72jlX1G3NYeWSm6PaRJFfLFGPOTZKq+u1MR3qtS1X9TFUdMF9369tJvpfkovkotNck+duqusYc1x69hZ/DRzNdS+v/zPvpwCS/njWue7UB10hyfpJvVdUtk/zhwn1vSXL9qnpkVV1pHusB830vSvLXVbV3TW5XVT8xn57wC0keXFW7VNXvZO04tnoM30ryjaq6QaYwuOK/kpyT5KlVdbWqunJV/ewa23hLkptX1UPm/XDFef/fqqp2q6oHVdW15lNYnp/kojW2AQAA7IBELwAAYLvp7mdkikBPzBSczsp0tNWb5lX+JsnxST6Z5KQkJ8zLttS/JTkkydcyXVfrN7r7gu7+VKZrbX040+kRb5vkg5ux3WtmOlLsa5lOOfjVJE+f7/uTTCHsjCQfSPKqJC/Z3IF39w8yRa57ZjqC7LlJHtrd/73OTTwmyW8m+eY81qMXtv3NJL88b/9Lma5ndtf57mdmCnfvzBSRXpzkKvN9v58pXH01ya2TfGgTY3hKkjsk+UaStyZ5w8IYfjg//82SfD7TqScPWb2Beay/kulaaV+cx/v3Sa40r/KQJGfOp098RKZTHwIAADuB6t7oGToAAAB2CFX15CQ36+4Hb++xAAAAsPU50gsAAAAAAIDhiV4AAAAAAAAMz+kNAQAAAAAAGJ4jvQAAAAAAABjertt7AJtr991377322mt7DwMAAAAAAIBt7GMf+9h53b3HWvcNF7322muvHH/88dt7GAAAAAAAAGxjVfW5Dd3n9IYAAAAAAAAMT/QCAAAAAABgeKIXAAAAAAAAwxO9AAAAAAAAGJ7oBQAAAAAAwPBELwAAAAAAAIYnegEAAAAAADA80QsAAAAAAIDhiV4AAAAAAAAMT/QCAAAAAABgeKIXAAAAAAAAwxO9AAAAAAAAGJ7oBQAAAAAAwPBELwAAAAAAAIYnegEAAAAAADA80QsAAAAAAIDhiV4AAAAAAAAMT/QCAAAAAABgeKIXAAAAAAAAwxO9AAAAAAAAGJ7oBQAAAAAAwPBELwAAAAAAAIYnegEAAAAAADA80QsAAAAAAIDhiV4AAAAAAAAMT/QCAAAAAABgeKIXAAAAAAAAwxO9AAAAAAAAGJ7oBQAAAAAAwPBELwAAAAAAAIYnegEAAAAAADA80QsAAAAAAIDhiV4AAAAAAAAMT/QCAAAAAABgeKIXAAAAAAAAwxO9AAAAAAAAGJ7oBQAAAAAAwPB23d4DYLn2Ovyt23sIwDZ25lPvtb2HAAAAAACwzTnSCwAAAAAAgOGJXgAAAAAAAAxP9AIAAAAAAGB4ohcAAAAAAADDE70AAAAAAAAYnugFAAAAAADA8EQvAAAAAAAAhid6AQAAAAAAMDzRCwAAAAAAgOGJXgAAAAAAAAxP9AIAAAAAAGB4ohcAAAAAAADDE70AAAAAAAAYnugFAAAAAADA8EQvAAAAAAAAhid6AQAAAAAAMDzRCwAAAAAAgOEtNXpV1T2q6rSqOr2qDl/j/odV1blVdeL87/eWOR4AAAAAAAB2TLsua8NVtUuSI5P8cpKzkxxXVcd096dWrXp0dx+2rHEAAAAAAACw41vmkV77Jzm9u8/o7h8kOSrJwUt8PgAAAAAAAHZSy4xeN0hy1sLts+dlq923qj5ZVa+rqj3X2lBVPbyqjq+q488999xljBUAAAAAAICBLfWaXuvw5iR7dfftkrwrycvWWqm7X9Dd+3X3fnvsscc2HSAAAAAAAACXf8uMXl9Isnjk1g3nZRfr7q929/fnmy9KcscljgcAAAAAAIAd1DKj13FJ9q6qm1TVbkkemOSYxRWq6voLNw9KcuoSxwMAAAAAAMAOatdlbbi7L6yqw5K8I8kuSV7S3adU1RFJju/uY5L8aVUdlOTCJP+b5GHLGg8AAAAAAAA7rqVFryTp7rcleduqZU9a+PgvkvzFMscAAAAAAADAjm+ZpzcEAAAAAACAbUL0AgAAAAAAYHiiFwAAAAAAAMMTvQAAAAAAABie6AUAAAAAAMDwRC8AAAAAAACGJ3oBAAAAAAAwPNELAAAAAACA4YleAAAAAAAADE/0AgAAAAAAYHiiFwAAAAAAAMMTvQAAAAAAABie6AUAAAAAAMDwRC8AAAAAAACGt+v2HgAAbC17Hf7W7T0EYBs786n32t5DAAAAAC4nHOkFAAAAAADA8EQvAAAAAAAAhid6AQAAAAAAMDzRCwAAAAAAgOGJXgAAAAAAAAxP9AIAAAAAAGB4ohcAAAAAAADDE70AAAAAAAAYnugFAAAAAADA8EQvAAAAAAAAhid6AQAAAAAAMDzRCwAAAAAAgOGJXgAAAAAAAAxP9AIAAAAAAGB4ohcAAAAAAADDE70AAAAAAAAYnugFAAAAAADA8EQvAAAAAAAAhid6AQAAAAAAMDzRCwAAAAAAgOGJXgAAAAAAAAxP9AIAAAAAAGB4ohcAAAAAAADDE70AAAAAAAAYnugFAAAAAADA8EQvAAAAAAAAhid6AQAAAAAAMDzRCwAAAAAAgOGJXgAAAAAAAAxP9AIAAAAAAGB4ohcAAAAAAADDE70AAAAAAAAYnugFAAAAAADA8EQvAAAAAAAAhid6AQAAAAAAMDzRCwAAAAAAgOGJXgAAAAAAAAxP9AIAAAAAAGB4ohcAAAAAAADDE70AAAAAAAAYnugFAAAAAADA8EQvAAAAAAAAhid6AQAAAAAAMDzRCwAAAAAAgOGJXgAAAAAAAAxP9AIAAAAAAGB4ohcAAAAAAADDE70AAAAAAAAYnugFAAAAAADA8EQvAAAAAAAAhid6AQAAAAAAMDzRCwAAAAAAgOGJXgAAAAAAAAxP9AIAAAAAAGB4ohcAAAAAAADDE70AAAAAAAAYnugFAAAAAADA8EQvAAAAAAAAhid6AQAAAAAAMDzRCwAAAAAAgOGJXgAAAAAAAAxP9AIAAAAAAGB4ohcAAAAAAADDE70AAAAAAAAYnugFAAAAAADA8EQvAAAAAAAAhid6AQAAAAAAMDzRCwAAAAAAgOGJXgAAAAAAAAxP9AIAAAAAAGB4ohcAAAAAAADDE70AAAAAAAAYnugFAAAAAADA8EQvAAAAAAAAhid6AQAAAAAAMDzRCwAAAAAAgOGJXgAAAAAAAAxP9AIAAAAAAGB4ohcAAAAAAADDE70AAAAAAAAYnugFAAAAAADA8EQvAAAAAAAAhid6AQAAAAAAMDzRCwAAAAAAgOGJXgAAAAAAAAxP9AIAAAAAAGB4ohcAAAAAAADDE70AAAAAAAAYnugFAAAAAADA8EQvAAAAAAAAhid6AQAAAAAAMDzRCwAAAAAAgOGJXgAAAAAAAAxP9AIAAAAAAGB4ohcAAAAAAADDE70AAAAAAAAYnugFAAAAAADA8EQvAAAAAAAAhid6AQAAAAAAMDzRCwAAAAAAgOGJXgAAAAAAAAxP9AIAAAAAAGB4ohcAAAAAAADDE70AAAAAAAAYnugFAAAAAADA8EQvAAAAAAAAhid6AQAAAAAAMDzRCwAAAAAAgOGJXgAAAAAAAAxP9AIAAAAAAGB4ohcAAAAAAADDE70AAAAAAAAYnugFAAAAAADA8EQvAAAAAAAAhid6AQAAAAAAMDzRCwAAAAAAgOGJXgAAAAAAAAxP9AIAAAAAAGB4ohcAAAAAAADDE70AAAAAAAAYnugFAAAAAADA8EQvAAAAAAAAhid6AQAAAAAAMDzRCwAAAAAAgOGJXgAAAAAAAAxP9AIAAAAAAGB4ohcAAAAAAADDW2r0qqp7VNVpVXV6VR2+kfXuW1VdVfstczwAAAAAAADsmJYWvapqlyRHJrlnkn2SHFpV+6yx3jWS/FmSjy5rLAAAAAAAAOzYlnmk1/5JTu/uM7r7B0mOSnLwGuv9dZK/T/K9JY4FAAAAAACAHdgyo9cNkpy1cPvsednFquoOSfbs7rdubENV9fCqOr6qjj/33HO3/kgBAAAAAAAY2lKv6bUxVXWFJM9M8uebWre7X9Dd+3X3fnvsscfyBwcAAAAAAMBQlhm9vpBkz4XbN5yXrbhGktskObaqzkxypyTHVNV+SxwTAAAAAAAAO6BlRq/jkuxdVTepqt2SPDDJMSt3dvc3unv37t6ru/dK8pEkB3X38UscEwAAAAAAADugpUWv7r4wyWFJ3pHk1CSv6e5TquqIqjpoWc8LAAAAAADAzmfXZW68u9+W5G2rlj1pA+seuMyxAAAAAAAAsONa5ukNAQAAAAAAYJsQvQAAAAAAABie6AUAAAAAAMDwRC8AAAAAAACGJ3oBAAAAAAAwPNELAAAAAACA4YleAAAAAAAADE/0AgAAAAAAYHiiFwAAAAAAAMMTvQAAAAAAABie6AUAAAAAAMDwRC8AAAAAAACGJ3oBAAAAAAAwPNELAAAAAACA4YleAAAAAAAADE/0AgAAAAAAYHiiFwAAAAAAAMMTvQAAAAAAABie6AUAAAAAAMDwRC8AAAAAAACGJ3oBAAAAAAAwPNELAAAAAACA4YleAAAAAAAADE/0AgAAAAAAYHiiFwAAAAAAAMMTvQAAAAAAABie6AUAAAAAAMDwRC8AAAAAAACGJ3oBAAAAAAAwPNELAAAAAACA4YleAAAAAAAADE/0AgAAAAAAYHiiFwAAAAAAAMMTvQAAAAAAABie6AUAAAAAAMDwRC8AAAAAAACGJ3oBAAAAAAAwPNELAAAAAACA4YleAAAAAAAADE/0AgAAAAAAYHiiFwAAAAAAAMMTvQAAAAAAABie6AUAAAAAAMDwRC8AAAAAAACGJ3oBAAAAAAAwPNELAAAAAACA4YleAAAAAAAADE/0AgAAAAAAYHiiFwAAAAAAAMMTvQAAAAAAABie6AUAAAAAAMDwRC8AAAAAAACGJ3oBAAAAAAAwPNELAAAAAACA4YleAAAAAAAADE/0AgAAAAAAYHiiFwAAAAAAAMMTvQAAAAAAABie6AUAAAAAAMDwRC8AAAAAAACGJ3oBAAAAAAAwPNELAAAAAACA4YleAAAAAAAADE/0AgAAAAAAYHiiFwAAAAAAAMMTvQAAAAAAABie6AUAAAAAAMDwRC8AAAAAAACGJ3oBAAAAAAAwPNELAAAAAACA4YleAAAAAAAADE/0AgAAAAAAYHiiFwAAAAAAAMMTvQAAAAAAABie6AUAAAAAAMDwRC8AAAAAAACGJ3oBAAAAAAAwPNELAAAAAACA4YleAAAAAAAADE/0AgAAAAAAYHiiFwAAAAAAAMMTvQAAAAAAABie6AUAAAAAAMDwRC8AAAAAAACGJ3oBAAAAAAAwPNELAAAAAACA4YleAAAAAAAADE/0AgAAAAAAYHiiFwAAAAAAAMMTvQAAAAAAABie6AUAAAAAAMDwRC8AAAAAAACGJ3oBAAAAAAAwPNELAAAAAACA4YleAAAAAAAADE/0AgAAAAAAYHiiFwAAAAAAAMMTvQAAAAAAABie6AUAAAAAAMDwRC8AAAAAAACGJ3oBAAAAAAAwPNELAAAAAACA4YleAAAAAAAADE/0AgAAAAAAYHiiFwAAAAAAAMMTvQAAAAAAABie6AUAAAAAAMDwRC8AAAAAAACGJ3oBAAAAAAAwPNELAAAAAACA4YleAAAAAAAADE/0AgAAAAAAYHiiFwAAAAAAAMMTvQAAAAAAABie6AUAAAAAAMDwRC8AAAAAAACGJ3oBAAAAAAAwPNELAAAAAACA4YleAAAAAAAADE/0AgAAAAAAYHiiFwAAAAAAAMMTvQAAAAAAABie6AUAAAAAAMDwRC8AAAAAAACGJ3oBAAAAAAAwPNELAAAAAACA4YleAAAAAAAADE/0AgAAAAAAYHiiFwAAAAAAAMMTvQAAAAAAABie6AUAAAAAAMDwRC8AAAAAAACGJ3oBAAAAAAAwPNELAAAAAACA4YleAAAAAAAADE/0AgAAAAAAYHiiFwAAAAAAAMMTvQAAAAAAABie6AUAAAAAAMDwRC8AAAAAAACGJ3oBAAAAAAAwPNELAAAAAACA4S01elXVParqtKo6vaoOX+P+R1TVSVV1YlV9oKr2WeZ4AAAAAAAA2DEtLXpV1S5JjkxyzyT7JDl0jaj1qu6+bXfvm+RpSZ65rPEAAAAAAACw41rmkV77Jzm9u8/o7h8kOSrJwYsrdPf5CzevlqSXOB4AAAAAAAB2ULsucds3SHLWwu2zkxyweqWq+uMkj06yW5K7LXE8AAAAAAAA7KCWek2v9ejuI7v7pkkel+SJa61TVQ+vquOr6vhzzz132w4QAAAAAACAy71lRq8vJNlz4fYN52UbclSSe691R3e/oLv36+799thjj603QgAAAAAAAHYIy4xexyXZu6puUlW7JXlgkmMWV6iqvRdu3ivJp5c4HgAAAAAAAHZQS7umV3dfWFWHJXlHkl2SvKS7T6mqI5Ic393HJDmsqn4pyQVJvpbkt5Y1HgAAAAAAAHZcS4teSdLdb0vytlXLnrTw8Z8t8/kBAAAAAADYOSzz9IYAAAAAAACwTYheAAAAAAAADE/0AgAAAAAAYHiiFwAAAAAAAMMTvQAAAAAAABie6AUAAAAAAMDwRC8AAAAAAACGJ3oBAAAAAAAwPNELAAAAAACA4YleAAAAAAAADE/0AgAAAAAAYHiiFwAAAAAAAMMTvQAAAAAAABie6AUAAAAAAMDwRC8AAAAAAACGJ3oBAAAAAAAwPNELAAAAAACA4YleAAAAAAAADE/0AgAAAAAAYHiiFwAAAAAAAMPbZPSqql+vKnEMAAAAAACAy631xKxDkny6qp5WVbdc9oAAAAAAAABgc20yenX3g5P8dJLPJHlpVX24qh5eVddY+ugAAAAAAABgHdZ12sLuPj/J65IcleT6Se6T5ISq+pMljg0AAAAAAADWZT3X9Dqoqt6Y5NgkV0yyf3ffM8ntk/z5cocHAAAAAAAAm7brOta5b5Jndff7Fxd293eq6neXMywAAAAAAABYv/VErycnOWflRlVdJcl1u/vM7n73sgYGAAAAAAAA67Wea3q9NslFC7d/OC8DAAAAAACAy4X1RK9du/sHKzfmj3db3pAAAAAAAABg86wnep1bVQet3Kiqg5Oct7whAQAAAAAAwOZZzzW9HpHklVX1nCSV5KwkD13qqAAAAAAAAGAzbDJ6dfdnktypqq4+3/7W0kcFAAAAAAAAm2E9R3qlqu6V5NZJrlxVSZLuPmKJ4wIAAAAAAIB12+Q1varqeUkOSfInmU5veP8kN17yuAAAAAAAAGDdNhm9ktylux+a5Gvd/ZQkd05y8+UOCwAAAAAAANZvPdHre/N/v1NVP5nkgiTXX96QAAAAAAAAYPOs55peb66qayd5epITknSSFy5zUAAAAAAAALA5Nhq9quoKSd7d3V9P8vqqekuSK3f3N7bF4AAAAAAAAGA9Nnp6w+6+KMmRC7e/L3gBAAAAAABwebOea3q9u6ruW1W19NEAAAAAAADAFlhP9PqDJK9N8v2qOr+qvllV5y95XAAAAAAAALBuG72mV5J09zW2xUAAAAAAAABgS20yelXVL6y1vLvfv/WHAwAAAAAAAJtvk9EryWMXPr5ykv2TfCzJ3ZYyIgAAAAAAANhM6zm94a8v3q6qPZP8w7IGBAAAAAAAAJvrClvwmLOT3GprDwQAAAAAAAC21Hqu6fXsJD3fvEKSfZOcsMQxAQAAAAAAwGZZzzW9jl/4+MIkr+7uDy5pPAAAAAAAALDZ1hO9Xpfke939wySpql2q6qrd/Z3lDg0AAAAAAADWZz3X9Hp3kqss3L5Kkv9YznAAAAAAAABg860nel25u7+1cmP++KrLGxIAAAAAAABsnvVEr29X1R1WblTVHZN8d3lDAgAAAAAAgM2znmt6PTLJa6vqi0kqyfWSHLLMQQEAAAAAAMDm2GT06u7jquqWSW4xLzqtuy9Y7rAAAAAAAABg/TZ5esOq+uMkV+vuk7v75CRXr6o/Wv7QAAAAAAAAYH3Wc02v3+/ur6/c6O6vJfn9pY0IAAAAAAAANtN6otcuVVUrN6pqlyS7LW9IAAAAAAAAsHk2eU2vJG9PcnRVPX++/QdJ/n15QwIAAAAAAIDNs57o9bgkD0/yiPn2J5Ncb2kjAgAAAAAAgM20ydMbdvdFST6a5Mwk+ye5W5JTlzssAAAAAAAAWL8NHulVVTdPcuj877wkRydJd9912wwNAAAAAAAA1mdjpzf87yT/meTXuvv0JKmqR22TUQEAAAAAAMBm2NjpDX8jyTlJ3ltVL6yquyepbTMsAAAAAAAAWL8NRq/uflN3PzDJLZO8N8kjk1ynqv65qn5lG40PAAAAAAAANmljR3olSbr72939qu7+9SQ3TPLxJI9b+sgAAAAAAABgnTYZvRZ199e6+wXdffdlDQgAAAAAAAA212ZFLwAAAAAAALg8Er0AAAAAAAAYnugFAAAAAADA8EQvAAAAAAAAhid6AQAAAAAAMDzRCwAAAAAAgOGJXgAAAAAAAAxP9AIAAAAAAGB4ohcAAAAAAADDE70AAAAAAAAYnugFAAAAAADA8EQvAAAAAAAAhid6AQAAAAAAMDzRCwAAAAAAgOGJXgAAAAAAAAxP9AIAAAAAAGB4ohcAAAAAAADDE70AAAAAAAAYnugFAAAAAADA8EQvAAAAAAAAhid6AQAAAAAAMDzRCwAAAAAAgOGJXgAAAAAAAAxP9AIAAAAAAGB4ohcAAAAAAADDE70AAAAAAAAYnugFAAAAAADA8EQvAAAAAAAAhid6AQAAAAAAMDzRCwAAAAAAgOGJXgAAAAAAAAxP9AIAAAAAAGB4ohcAAAAAAADDE70AAAAAAAAYnugFAAAAAADA8EQvAAAAAAAAhid6AQAAAAAAMDzRCwAAAAAAgOGJXgAAAAAAAAxP9AIAAAAAAGB4ohcAAAAAAADDE70AAAAAAAAYnugFAAAAAADA8EQvAAAAAAAAhid6AQAAAAAAMDzRCwAAAAAAgOGJXgAAAAAAAAxP9AIAAAAAAGB4ohcAAAAAAADDE70AAAAAAAAYnugFAAAAAADA8EQvAAAAAAAAhid6AQAAAAAAMDzRCwAAAAAAgOGJXgAAAAAAAAxP9AIAAAAAAGB4ohcAAAAAAADDE70AAAAAAAAYnugFAAAAAADA8EQvAAAAAAAAhid6AQAAAAAAMDzRCwAAAAAAgOGJXgAAAAAAAAxP9AIAAAAAAGB4ohcAAAAAAADDE70AAAAAAAAYnugFAAAAAADA8EQvAAAAAAAAhid6AQAAAAAAMDzRCwAAAAAAgOGJXgAAAAAAAAxP9AIAAAAAAGB4ohcAAAAAAADDE70AAAAAAAAYnugFAAAAAADA8EQvAAAAAAAAhrfU6FVV96iq06rq9Ko6fI37H11Vn6qqT1bVu6vqxsscDwAAAAAAADumpUWvqtolyZFJ7plknySHVtU+q1b7eJL9uvt2SV6X5GnLGg8AAAAAAAA7rmUe6bV/ktO7+4zu/kGSo5IcvLhCd7+3u78z3/xIkhsucTwAAAAAAADsoJYZvW6Q5KyF22fPyzbkd5P8+xLHAwAAAAAAwA5q1+09gCSpqgcn2S/JL27g/ocneXiS3OhGN9qGIwMAAAAAAGAEyzzS6wtJ9ly4fcN52aVU1S8leUKSg7r7+2ttqLtf0N37dfd+e+yxx1IGCwAAAAAAwLiWGb2OS7J3Vd2kqnZL8sAkxyyuUFU/neT5mYLXV5Y4FgAAAAAAAHZgS4te3X1hksOSvCPJqUle092nVNURVXXQvNrTk1w9yWur6sSqOmYDmwMAAAAAAIANWuo1vbr7bUnetmrZkxY+/qVlPj8AAAAAAAA7h2We3hAAAAAAAAC2CdELAAAAAACA4YleAAAAAAAADE/0AgAAAAAAYHiiFwAAAAAAAMMTvQAAAAAAABie6AUAAAAAAMDwRC8AAAAAAACGJ3oBAAAAAAAwPNELAAAAAACA4YleAAAAAAAADE/0AgAAAAAAYHiiFwAAAAAAAMMTvQAAAAAAABie6AUAAAAAAMDwRC8AAAAAAACGJ3oBAAAAAAAwPNELAAAAAACA4YleAAAAAAAADE/0AgAAAAAAYHiiFwAAAAAAAMMTvQAAAAAAABie6AUAAAAAAMDwRC8AAAAAAACGJ3oBAAAAAAAwPNELAAAAAACA4YleAAAAAAAADE/0AgAAAAAAYHiiFwAAAAAAAMMTvQAAAAAAABie6AUAAAAAAMDwRC8AAAAAAACGJ3oBAAAAAAAwPNELAAAAAACA4YleAAAAAAAADE/0AgAAAAAAYHiiFwAAAAAAAMMTvQAAAAAAABie6AUAAAAAAMDwRC8AAAAAAACGJ3oBAAAAAAAwPNELAAAAAACA4YleAAAAAAAADE/0AgAAAAAAYHiiFwAAAAAAAMMTvQAAAAAAABie6AUAAAAAAMDwRC8AAAAAAACGJ3oBAAAAAAAwPNELAAAAAACA4YleAAAAAAAADE/0AgAAAAAAYHiiFwAAAAAAAMMTvQAAAAAAABie6AUAAAAAAMDwRC8AAAAAAACGJ3oBAAAAAAAwPNELAAAAAACA4YleAAAAAAAADE/0AgAAAAAAYHiiFwAAAAAAAMMTvQAAAAAAABie6AUAAAAAAMDwRC8AAAAAAACGJ3oBAAAAAAAwPNELAAAAAACA4YleAAAAAAAADE/0AgAAAAAAYHiiFwAAAAAAAMMTvQAAAAAAABie6AUAAAAAAMDwRC8AAAAAAACGJ3oBAAAAAAAwPNELAAAAAACA4YleAAAAAAAADE/0AgAAAAAAYHiiFwAAAAAAAMMTvQAAAAAAABie6AUAAAAAAMDwRC8AAAAAAACGJ3oBAAAAAAAwPNELAAAAAACA4YleAAAAAAAADE/0AgAAAAAAYHiiFwAAAAAAAMMTvQAAAAAAABie6AUAAAAAAMDwRC8AAAAAAACGJ3oBAAAAAAAwPNELAAAAAACA4YleAAAAAAAADE/0AgAAAAAAYHiiFwAAAAAAAMMTvQAAAAAAABie6AUAAAAAAMDwRC8AAAAAAACGJ3oBAAAAAAAwPNELAAAAAACA4YleAAAAAAAADE/0AgAAAAAAYHiiFwAAAAAAAMMTvQAAAAAAABie6AUAAAAAAMDwRC8AAAAAAACGJ3oBAAAAAAAwPNELAAAAAACA4YleAAAAAAAADE/0AgAAAAAAYHiiFwAAAAAAAMMTvQAAAAAAABie6AUAAAAAAMDwRC8AAAAAAACGJ3oBAAAAAAAwPNELAAAAAACA4YleAAAAAAAADE/0AgAAAAAAYHiiFwAAAAAAAMMTvQAAAAAAABie6AUAAAAAAMDwRC8AAAAAAACGJ3oBAAAAAAAwPNELAAAAAACA4YleAAAAAAAADE/0AgAAAAAAYHiiFwAAAAAAAMMTvQAAAAAAABie6AUAAAAAAMDwRC8AAAAAAACGJ3oBAAAAAAAwPNELAAAAAACA4YleAAAAAAAADE/0AgAAAAAAYHiiFwAAAAAAAMMTvQAAAAAAABie6AUAAAAAAMDwRC8AAAAAAACGJ3oBAAAAAAAwPNELAAAAAACA4YleAAAAAAAADE/0AgAAAAAAYHiiFwAAAAAAAMMTvQAAAAAAABie6AUAAAAAAMDwlhq9quoeVXVaVZ1eVYevcf8vVNUJVXVhVd1vmWMBAAAAAABgx7W06FVVuyQ5Msk9k+yT5NCq2mfVap9P8rAkr1rWOAAAAAAAANjx7brEbe+f5PTuPiNJquqoJAcn+dTKCt195nzfRUscBwAAAAAAADu4ZZ7e8AZJzlq4ffa8bLNV1cOr6viqOv7cc8/dKoMDAAAAAABgx7HUa3ptLd39gu7er7v322OPPbb3cAAAAAAAALicWWb0+kKSPRdu33BeBgAAAAAAAFvVMqPXcUn2rqqbVNVuSR6Y5JglPh8AAAAAAAA7qaVFr+6+MMlhSd6R5NQkr+nuU6rqiKo6KEmq6meq6uwk90/y/Ko6ZVnjAQAAAAAAYMe16zI33t1vS/K2VcuetPDxcZlOewgAAAAAAABbbJmnNwQAAAAAAIBtQvQCAAAAAABgeKIXAAAAAAAAwxO9AAAAAAAAGJ7oBQAAAAAAwPBELwAAAAAAAIYnegEAAAAAADA80QsAAAAAAIDhiV4AAAAAAAAMT/QCAAAAAABgeKIXAAAAAAAAwxO9AAAAAAAAGJ7oBQAAAAAAwPBELwAAAAAAAIYnegEAAAAAADA80QsAAAAAAIDhiV4AAAAAAAAMT/QCAAAAAABgeKIXAAAAAAAAwxO9AAAAAAAAGJ7oBQAAAAAAwPBELwAAAAAAAIYnegEAAAAAADA80QsAAAAAAIDhiV4AAAAAAAAMT/QCAAAAAABgeKIXAAAAAAAAwxO9AAAAAAAAGJ7oBQAAAAAAwPBELwAAAAAAAIYnegEAAAAAADA80QsAAAAAAIDhiV4AAAAAAAAMT/QCAAAAAABgeKIXAAAAAAAAwxO9AAAAAAAAGJ7oBQAAAAAAwPBELwAAAAAAAIYnegEAAAAAADA80QsAAAAAAIDhiV4AAAAAAAAMT/QCAAAAAABgeKIXAAAAAAAAwxO9AAAAAAAAGJ7oBQAAAAAAwPBELwAAAAAAAIYnegEAAAAAADA80QsAAAAAAIDhiV4AAAAAAAAMT/QCAAAAAABgeKIXAAAAAAAAwxO9AAAAAAAAGJ7oBQAAAAAAwPBELwAAAAAAAIYnegEAAAAAADA80QsAAAAAAIDhiV4AAAAAAAAMT/QCAAAAAABgeKIXAAAAAAAAwxO9AAAAAAAAGJ7oBQAAAAAAwPBELwAAAAAAAIYnegEAAAAAADA80QsAAAAAAIDhiV4AAAAAAAAMT/QCAAAAAABgeKIXAAAAAAAAwxO9AAAAAAAAGJ7oBQAAAAAAwPBELwAAAAAAAIYnegEAAAAAADA80QsAAAAAAIDhiV4AAAAAAAAMT/QCAAAAAABgeKIXAAAAAAAAwxO9AAAAAAAAGJ7oBQAAAAAAwPBELwAAAAAAAIYnegEAAAAAADA80QsAAAAAAIDhiV4AAAAAAAAMT/QCAAAAAABgeKIXAAAAAAAAwxO9AAAAAAAAGJ7oBQAAAAAAwPBELwAAAAAAAIYnegEAAAAAADA80QsAAAAAAIDhiV4AAAAAAAAMT/QCAAAAAABgeKIXAAAAAAAAwxO9AAAAAAAAGJ7oBQAAAAAAwPBELwAAAAAAAIYnegEAAAAAADA80QsAAAAAAIDhiV4AAAAAAAAMT/QCAAAAAABgeKIXAAAAAAAAwxO9AAAAAAAAGJ7oBQAAAAAAwPBELwAAAAAAAIYnegEAAAAAADA80QsAAAAAAIDhiV4AAAAAAAAMT/QCAAAAAABgeKIXAAAAAAAAwxO9AAAAAAAAGJ7oBQAAAAAAwPBELwAAAAAAAIYnegEAAAAAADA80QsAAAAAAIDhiV4AAAAAAAAMT/QCAAAAAABgeKIXAAAAAAAAwxO9AAAAAAAAGJ7oBQAAAAAAwPBELwAAAAAAAIYnegEAAAAAADA80QsAAAAAAIDhiV4AAAAAAAAMT/QCAAAAAABgeKIXAAAAAAAAwxO9AAAAAAAAGJ7oBQAAAAAAwPBELwAAAAAAAIYnegEAAAAAADA80QsAAAAAAIDhiV4AAAAAAAAMb9ftPQAAAGDz7XX4W7f3EIBt7Myn3mt7DwGAbcDvebDz8Xve1uNILwAAAAAAAIYnegEAAAAAADA80QsAAAAAAIDhiV4AAAAAAAAMT/QCAAAAAABgeKIXAAAAAAAAwxO9AAAAAAAAGJ7oBQAAAAAAwPBELwAAAAAAAIa36/YeAAAAAMDG7HX4W7f3EIBt7Myn3mt7DwGAATnSCwAAAAAAgOGJXgAAAAAAAAxvqdGrqu5RVadV1elVdfga91+pqo6e7/9oVe21zPEAAAAAAACwY1pa9KqqXZIcmeSeSfZJcmhV7bNqtd9N8rXuvlmSZyX5+2WNBwAAAAAAgB3XMo/02j/J6d19Rnf/IMlRSQ5etc7BSV42f/y6JHevqlrimAAAAAAAANgBVXcvZ8NV90tyj+7+vfn2Q5Ic0N2HLaxz8rzO2fPtz8zrnLdqWw9P8vD55i2SnLaUQcOOZfck521yLYAdgzkP2JmY84CdiTkP2JmY82B9btzde6x1x67beiRbortfkOQF23scMJKqOr6799ve4wDYFsx5wM7EnAfsTMx5wM7EnAeX3TJPb/iFJHsu3L7hvGzNdapq1yTXSvLVJY4JAAAAAACAHdAyo9dxSfauqptU1W5JHpjkmFXrHJPkt+aP75fkPb2s8y0CAAAAAACww1ra6Q27+8KqOizJO5LskuQl3X1KVR2R5PjuPibJi5P8a1WdnuR/M4UxYOtwSlBgZ2LOA3Ym5jxgZ2LOA3Ym5jy4jMqBVQAAAAAAAIxumac3BAAAAAAAgG1C9AIAAAAAAGB4ohdsQFV9a3uPYWOq6syq2n17jwNYjh1tDqqqY6vqtKr6RFUdV1X7zss/vvDxrlX1rap68MLjPlZVd9ja41+Wqjqwqu6ycPsRVfXQrbDdvaqqq+pvFpbtXlUXVNVzVq17YlUdtWrZS6vqs/N9J1bVhy7rmOCyMs9d/DjzXC6e5747z1GfqqqXV9UVF56zq+r3Ftbfd172mPn2narqo/PjT62qJ8/LH1ZV5y7MfydW1T6XdbywWlXdsKr+rao+XVWfqap/rKrd1vG4x2/h8726qj5ZVY/aksdvDfP35ls2Y/01v8+r6vZVdeLCeofO663MAbetqk8u4VNYmqp6ZFVddeH226rq2lthu0+e576brXqurqr9FpatzJH3WPX4H66aDw+/rGNi52GeW9f65rnLvt0nV9UXFvbhoQv3vbSqvlNV11hY9g/zfLf7fPsJVXXK/P/OiVV1wLx85Xf1lfnvdZd1rFx+iV7AVlVVu27vMQCXWw/q7tsneW6Sp8/LPphk5cXT2yf5n5XbVXW1JDdN8oltPM7L4sBc8vmku5/X3S/fStv+bJJ7Ldy+f5JTFleoqlsl2SXJz8/7b9Fju3vf+d9dAiyDee6y+Ux375vktklumOQBC/edvOr2obn0fntZkofPj79Nktcs3Hf0wvy3b3d/aiuNF5IkVVVJ3pDkTd29d5KbJ7l6kr9dx8M3+8Xgqrpekp/p7tt197M29/Hb2Vrf5ycludHCi5h3SXJqkp9euD3aG3YemeTiF4O7+1e7++tbadsnJXngwu0f+Z0w0xz5gfm/i767aj586lYaEzs489xmMc9dds+a9+HBSZ6/Egdnp8/LU1VXSHK3JF+Yb985ya8luUN33y7JLyU5a+GxD1qY/+63lcbK5ZDoBZswv6vj2Kp6XVX9d1W9cv5hv3q961fV++d3C5xcVT8/L//nqjp+fpfBUxbWP7Oq/u+8/vFVdYeqesf8bplHLDz3+6vqrfO7EZ43T+irn/vBVfVf87aeX1W7rLHOk2p61/HJVfWClc+hqm5WVf9R07uST6iqm87LH1dVJ83LnzovO7bmd4/VdITBmfPHD6uqY6rqPUneXVVXr6p3z9s7qaoOXhjHQ+d3W3yiqv61qq5R09EHK+9uuebibdjZ7Shz0CofTnKD+eMP5ZIXT++S5HlJ9p1v75/kY939w1XPt1dV/ec8x5xQ8xEHa+2DqtqlpneDnTzPR4+a193YfPamqnrXvI8Oq6pH13Skxkeq6scXHv+PC8+1f1XtleQRSR41L//5mt6ltnIUwr7zNj5ZVW+sqh9b2Nbfz/vwf1a+dmv4TpJT65J38R6SS7+om0wvbPxrkndm/kMALu/Mc+a51eb98V8L+zBJPpfkylV13fn/j3sk+feF+6+T5JyVxwtbbGN3S/K97v6X5OL/hx+V5Heq6qrz993FR2ZX1Vvm+eepSa4yfz+9cvVGq+rKVfUv8/f2x6vqrvNd70xyg5Xvw1WPuf/8PfuJqnr/vGxDc8qBVfW+mo7cOKOqnlpVD5q/V0+qS/42fOk8Px4/fw//2hpjvVpVvWR+7Mdr4W/AtSx+n3f3RUmOT3LAfPcdkxyZS8+dH1zjOX+/pr9xP1FVr6/5iIMN7INbL8zjn6yqvef9cvLC9h5TlxwlemxVPWv+nE+tqp+pqjfUdITL3yzs15WfW6fW9HPsqlX1p0l+Msl7q+q987pn1iVHITx6Ht/JVfXIhW2dWlUvrOnn2Tur6iob2H1vyiUv+N40yTeSnLfweVSmEPawJL9cVVfe2NcC1sk8Z57blvPcyj78dKa/g39sYfFRmf4WTqY3Y30wyYXz7esnOa+7vz8//rzu/uLGnoMdk+gF6/PTmd7BsE+Sn0rys2us85tJ3jG/E+H2SU6clz+hu/dLcrskv1hVt1t4zOfn9f8zyUuT3C/JnZI8ZWGd/ZP8yfzcN03yG4tPWtO7+g9J8rPztn6Y5EFrjO853f0z3X2bJFfJ9M6HJHllkiPndyXfJck5VXXPTL9EHzAvf9rau+VS7pDkft39i0m+l+Q+3X2HJHdN8oya3DrJE5Pcbd7un3X3N5Mcm0uOXnhgkjd09wXreE7YWewIc9Cie2T6Yz259BEQd0ny/iTfr+kdcBt6t9tXkvzyPMcckuSfNrIP9s30R8Ztuvu2Sf5lE2NLpiMEfiPJz2R65+J3uvunM72IvXgKr6vOz/VHSV7S3WdmejH7WfM7x/5z1XZfnuRx8zvOTkryVwv37drd+2f6Ov9VNuyoJA+sqj0z7evVv8AfMq/z6vzoO3ufXpecyuFH/uCE7cw8d2k78zyX+QXaA5K8fdVdr8v0Qu5dkpyQ5PsL9z0ryWk1xbY/WPUi7yF16dN5bfQFFtgCt07yscUF3X1+ks8nudmaj5jWOTyXHHmz1rzyx9NqfdtMP9dfNv+/fVDmIwnW+D58UpL/b/5766B52YbmlGSaSx6R5FZJHpLk5vP36osyzY0r9so0X94ryfPWCClPSPKe+bF3zfR7x+qjzi+2xvf5B5PcZX7MRZn+RlycO9eaK98w/417+0xHTPzuRvbBI5L84zyn7Zfk7A2NbcEP5p8vz0vyb5m+HrdJ8rCq+ol5nVskeW533yrJ+Un+qLv/KdPvaHft7rsubrCq7pjkt+fP/U5Jfr+qVo702DvT3+a3TvL1JPfdwLjOT3JWVd0m09/PR6+6/y5JPtvdn8ml/9ZOLokPK/8OCayPec48ty3nuZVt3SHJp7v7KwuL/yfJHjW9uerQTH//rnhnkj3ncPncqvrFVZt85cL89/SwwxK9YH3+q7vPnt+ZcWKmH4SrHZfkt+d3TNx2jjlJ8oCqOiHJxzP9krB4DYFj5v+elOSj3f3N7j430wsh11547jPmd4i8OsnPrXreu2d6h8hxNZ0f+O6ZXixa7a41XefgpEzv0Ln1/GLLDbr7jUnS3d/r7u9kOvz3X+aP093/u/HdkyR518J6leTvajof8X9kepfudefnfW13n7dquy/K9AMx83/X82IN7Ex2hDkomX7B/GymPxaOTJLu/lyS3Wo6fcUtk5w2fy4HZAPvdktyxSQvnOez1y58TmvtgzOS/FRVPbumaxqcv4GxLXrvwr74RpI3z8tPyqX3/avnz+H9Sa5ZGzl/eVVdK8m1u/t986KXJfmFhVXeMP/3Y1n767vi7Ul+OWu8wFHTER3ndffnk7w7yU/XfMTGbPH0hpt6wR62NfPcpe2s89xN53385STndPfqa1u8JlP0OnRlbCu6+4hML/C8M1McXAxmq09v+N0NfR5wOfNzSV6RJN3935mOeLz5Jh7zwSQvrarfz3TK42TDc0qSHNfd5/T0rvjPZPoeSn50PnhNd1/U07vuz8g0ny36lSSHz9/Dxya5cpIbrTG+DX2frxwVu/88ps8kuVlV7ZHk6vPt1W5T05EdJ2V6M8KtN7IPPpzk8VX1uCQ3Xuc8sPgz5JSF/XRGkj3n+87q7pV5/BX50Z8hq/1ckjd297e7+1uZ5saVo1g+290nzh9v6nfCozL9PnjvJG9cdd/ii8BH5dJvhFp9esPVwQy2NfOceW4tj6qqU5J8NGufQvMNmebAAzK9uS1JMj/fHZM8PMm5SY6uqoctPG7x9IaP3cTnwcBEL1ifxXeR/jDJrlV1wMK7Aw6aXwz4hUznkX1pTafxu0mSxyS5e0/veH1rph+Kq7d70arnuCjJyrWxetVYVt+uJC9bmLRv0d1PvtQK07tLnpvpSKzbJnnhqnGs14W5ZN5Y/fhvL3z8oCR7JLnj/A6TL2/s+eYfnntV1YFJdunukze0Luykhp6DFjwo0wvFL0vy7IXlH8r0IuY53d1JPpLpKI/9M/3ivtqjMs0rt8/0AuduycUvyl5qH3T31+b1js30zrcXzdvY2Hy2el8s7qfF6xZuat9sjpXn+OGq57j0E3T/INMfB3+e6YiHRYcmuWVNpzD7TJJrZhPvnIPLEfPcpe2s89zKNTBumuSOVXXQ4p3d/aUkF2SK/+9e/eDu/kx3/3OmMHn7hXcow7J9KtOLbBerqmtmejH09Fz6+zHZwN9GVfXHC/PeT67niavqb1cekyTd/YhMZ9fYM8nH5u+DNeeU2daaDyrJfRfmyht196lrDHlD3+cfyXT06c/mknnx7Ewvaq41TybTEbyHzX/jPiXzfl1rH3T3qzIdDfHdJG+rqrtl01+XrfEzZHP8yM/Cjaz7lkxHrHy+p6NtkiQ1nX73vkmeNP9O+Owk96hLriMEW8o8Z57LBm5vjvXOc8/q6Wiw+yZ5cf3oUXdHJ/nrTG/Av+hSg5tOc31sd/9VksPib+KdkugFW6i7P7rwg+6Yqrpxki939wszvdhwh0wvOH47yTeq6rpJ7rkFT7V/Vd2kputLHJLpYrSL3p3kflV1nSSpqh+fx7Jo5YfDeVV19Uyn9sn87uCzq+re82OvVNP5gd+V6V3EK+cKXjlS4Mxc8kvOxi74eK0kX+nuC2o6H/PKeN6T5P4rL0CsOgLh5UleFUd5wboMNgctjruT/GWSO1XVyjvnPpTpdFcrv+ivnF7rS939jTU2c61MLxxflOmP/V3m5/6RfVDTOcWv0N2vz/RHwR3mbZyZ9c1nG3PI/Lw/l+Qb81i/meRHXlSY7/taXXI++ocked/q9dbpGZlOH3bxUbjz1+cBmY782Ku798p0mtrVpziEYZjndt55rqezAhye5C/WuPtJmebA1ddBu1fVxdeC2zvTCylf35Lnhy3w7iRXraqHJheHh2ckeWlPZ884M8m+VXWFmk5RvP/CYy+o+XrG3X3kwrz3xUzvXn/QvM2bZ3px+bTFJ+7uJ6w8Zl7vpvP8+aRM73LfMxuYUzbT/efx3zRT3D9t1f3vSPInK9+HdcmprNa0+vt8/tv0rExn/licKx+ZtY+ITaa56Jx5/118FPta+6CqfirJGT2dkuvfMp0S98tJrlNVP1FVV8ollwDYHDeqqjvPH/9mLvkZsuZcmelreu+arolztST3ycJRCus1/3/1uPzoERB3T/LJ7t5z/p3wxklePz8PXBbmOfNcsg3nuSTp7mMyXQvtt1Yt/1ymMys8d3F5Vd2iqvZeWLRvpqMH2cmIXrD1HJjkE1X18UwvEPxjd38i06l2/jtT0NnQD7GNOS7JczKdu/ezWXXqgp4u0v3EJO+s6XSC78p04cbFdb6e6eiukzP9kD5u4e6HJPnT+bEfSnK97n57pkOcj5/fSfOYed3/l+QP589x942M+ZVJ9qvp8OuHZvr8092nZPql/H1V9Ykkz1z1mB/LqlPVAOt2YC6nc9BqPZ1m4RlJVk4n8MFMf1R8eL7/nEx/pKx1TvNk+sX2t+Z55Ja55EjTA7NqH2Q6veqx81z2ilzyAup657ON+d78+OflknOrvznJfWqNCy5n+kX96fN+2jfJEVvypN19Sne/bNXin0/yhb70RXrfn2Sfqlr5eixe0+vEqtotMJYDY547MDvBPDd7U6YX1y71HN39oe5+0xrrPyTTNb1OTPKvmU5fsxLGVl/T6y5rPB622By775PpBdNPZ7reyPeSPH5e5YOZ5pdPZbrOzAkLD39Bkk/W2tfbfG6SK8x/Vx2d5GE9nXZqY55eVSdV1cmZ5phPZMNzyub4fJL/SvLvSR7R3d9bdf9fZzq92CdrOiXVX69jm2/Kpb/PP5jkSt191nz7w5nmzg3NlX+Z6dRXH8z8N+dsrX3wgCQnz3PEbZK8vKfrSB8xf17vWrWN9TotyR9X1amZ/p7953n5C5K8vareu7hyd5+Q6ciN/5rH/qLu/vgWPG+6+6h5e4sOzY+e7vD1ueSNUKuv6fXULXludj7muSTmuW0+z82OSPLomt6gtvg8z+8fPSXk1TNdF+5T8++j+yR58sL9i9f0+o/LMCYu52qas4DLo5pO9/eY7t6Sd2IMparul+Tg7n7I9h4LMNmZ5qDNVVXHZto3x2/vsQBbzjy3YeY5YEVVvTTJW7p79amVd2pVtVem/XKb7T0W4LIxz63NPMeoNnZ+YIBtoqqenel0RL+6vccCAAAAAMCYHOkFAAAAAADA8FzTCwAAAAAAgOGJXgAAAAAAAAxP9AIAAAAAAGB4ohcAAAAAAADDE70AAAAAAAAY3v8P00ChEMqs3sgAAAAASUVORK5CYII=\n"
          },
          "metadata": {
            "needs_background": "light"
          }
        }
      ]
    },
    {
      "cell_type": "markdown",
      "source": [
        "## DONT DO 4.) Plot in and out of sample accuracy"
      ],
      "metadata": {
        "id": "8bncNwh8tKiE"
      }
    },
    {
      "cell_type": "code",
      "source": [
        "import matplotlib.pyplot as plt\n",
        "\n",
        "# Make predictions on full dataset\n",
        "\n",
        "test_predict = model.predict(x_test)\n",
        "test_predictions = (test_predict+1).reshape(1,-1) * np.cumprod(y_test+1)\n",
        "\n",
        "train_predict = model.predict(x_train)\n",
        "train_predictions = (train_predict+1).reshape(1,-1) * np.cumprod(y_train+1)\n",
        "\n",
        "\n",
        "\n",
        "plt.plot(stock_data[:training_data_len- input_size].index, np.cumprod(y_train+1), label=\"Training Data\")\n",
        "plt.plot(stock_data[:training_data_len- input_size].index, train_predictions[0], label=\"Training Predictions\")\n",
        "end_val = np.cumprod(y_train+1)[-1]\n",
        "test_predict = model.predict(x_test)\n",
        "test_predictions = (test_predict+1).reshape(1,-1) * (np.cumprod((y_test+1))*end_val)\n",
        "plt.plot(stock_data[training_data_len+1:].index, np.cumprod((y_test+1))*end_val,label=\"Test Data\")\n",
        "plt.plot(stock_data[training_data_len+1:].index, test_predictions[0], label=\"Test Predictions\")\n",
        "plt.xlabel(\"Date\")\n",
        "plt.ylabel(\"Stock Price\")\n",
        "plt.legend()\n",
        "plt.show()"
      ],
      "metadata": {
        "id": "d698mdExtfHp"
      },
      "execution_count": null,
      "outputs": []
    },
    {
      "cell_type": "code",
      "source": [],
      "metadata": {
        "id": "jVPe8djTn1_2"
      },
      "execution_count": null,
      "outputs": []
    },
    {
      "cell_type": "code",
      "source": [],
      "metadata": {
        "id": "QCY8DfMEtUln"
      },
      "execution_count": null,
      "outputs": []
    },
    {
      "cell_type": "markdown",
      "source": [
        "#5.) Write an observation/conclusion about the graphs from Q4 and Q3"
      ],
      "metadata": {
        "id": "bK_jyyEEtTUB"
      }
    },
    {
      "cell_type": "code",
      "source": [
        "# The in-sample accuracy (RNN) and in-sample Random Walk (RW) accuracy are both quite low, around 51%. \n",
        "## This suggests that the model is likely unable to effectively capture the patterns in the data (Kellog stock) and make accurate predictions in the future\n",
        "\n",
        "# The in-sample random walk assumption RMSE, has a value of ~0.01 -- and is lower than the  out-of-sample random walk assumption (RMSE).\n",
        "## This suggests that the model is overfitting to the training data and not generalizing well to new data.\n",
        "\n",
        "# In conclusion, the results tell me that my model likely needs  further tuning or a different approach to predict the behavior of Kellog (K) stock.\n"
      ],
      "metadata": {
        "id": "FlD_yx0cshJ7"
      },
      "execution_count": null,
      "outputs": []
    },
    {
      "cell_type": "code",
      "source": [],
      "metadata": {
        "id": "N5fbjajz-YCF"
      },
      "execution_count": null,
      "outputs": []
    },
    {
      "cell_type": "code",
      "source": [],
      "metadata": {
        "id": "JKaNjoQlBPbr"
      },
      "execution_count": null,
      "outputs": []
    },
    {
      "cell_type": "markdown",
      "source": [
        "# 6.) Create a parameter for number of lags in your input layer. Do a 3-fold CV to test three different time lags. i.e. Tested using 5,10,20 days of previous price data to forecast"
      ],
      "metadata": {
        "id": "pFtrp-lmtw6t"
      }
    },
    {
      "cell_type": "code",
      "source": [
        "import numpy as np\n",
        "\n",
        "\n",
        "\n",
        "# Define the length of the sliding window\n",
        "window_length = 5\n",
        "\n",
        "# Calculate the number of samples that can be created from the data using the window length\n",
        "n_samples = stock_data.shape[0] - window_length + 1\n",
        "\n",
        "# Create an empty array to hold the sliding window data\n",
        "sliding_window_data = np.empty((n_samples, window_length, stock_data.shape[1]))\n",
        "\n",
        "# Populate the sliding window data array by iterating over the original data\n",
        "for i in range(n_samples):\n",
        "    sliding_window_data[i] = stock_data[i:i+window_length]\n",
        "\n",
        "# Now the sliding window data array has shape (220196, 5, 10), which can be reshaped to (220196, 50)\n",
        "sliding_window_data = sliding_window_data.reshape((n_samples, -1))\n"
      ],
      "metadata": {
        "id": "S7Ei4yvL1R9q"
      },
      "execution_count": null,
      "outputs": []
    },
    {
      "cell_type": "code",
      "source": [
        "from sklearn.model_selection import GridSearchCV\n",
        "from keras.wrappers.scikit_learn import KerasRegressor\n",
        "from keras.layers import Dense, LSTM, TimeDistributed\n",
        "from keras.models import Sequential\n",
        "\n",
        "def create_model(lags):\n",
        "    model = Sequential()\n",
        "    model.add(LSTM(10, input_shape=(lags, 1)))\n",
        "    model.add(Dense(1, activation='sigmoid'))\n",
        "    model.compile(loss='binary_crossentropy', optimizer='adam', metrics=['accuracy'])\n",
        "    return model\n"
      ],
      "metadata": {
        "id": "siFX-Pwf15uI"
      },
      "execution_count": null,
      "outputs": []
    },
    {
      "cell_type": "code",
      "source": [
        "param_grid = {'lags': [5, 10, 20],\n",
        "              'batch_size': [10, 20, 100],\n",
        "              'epochs': [1]}\n"
      ],
      "metadata": {
        "id": "WuRCVXYRQh8T"
      },
      "execution_count": null,
      "outputs": []
    },
    {
      "cell_type": "code",
      "source": [
        "model = KerasRegressor(build_fn=lambda lags: create_model(lags=lags), verbose=0)"
      ],
      "metadata": {
        "colab": {
          "base_uri": "https://localhost:8080/"
        },
        "id": "pko3NYyDQ560",
        "outputId": "0629e494-4d28-472f-8827-bc8bfd82200f"
      },
      "execution_count": null,
      "outputs": [
        {
          "output_type": "stream",
          "name": "stderr",
          "text": [
            "<ipython-input-86-6e7977793596>:1: DeprecationWarning: KerasRegressor is deprecated, use Sci-Keras (https://github.com/adriangb/scikeras) instead. See https://www.adriangb.com/scikeras/stable/migration.html for help migrating.\n",
            "  model = KerasRegressor(build_fn=lambda lags: create_model(lags=lags), verbose=0)\n"
          ]
        }
      ]
    },
    {
      "cell_type": "code",
      "source": [
        "grid = GridSearchCV(estimator=model, param_grid=param_grid, n_jobs=-1, cv=3)\n",
        "grid_result = grid.fit(x_train, y_train)\n",
        "\n",
        "print(\"Best: %f using %s\" % (grid_result.best_score_, grid_result.best_params_))"
      ],
      "metadata": {
        "colab": {
          "base_uri": "https://localhost:8080/"
        },
        "id": "1Ng-WcrzQkys",
        "outputId": "92dcb679-f642-4463-90b3-924a506bb688"
      },
      "execution_count": null,
      "outputs": [
        {
          "output_type": "stream",
          "name": "stderr",
          "text": [
            "/usr/local/lib/python3.8/dist-packages/sklearn/model_selection/_validation.py:372: FitFailedWarning: \n",
            "18 fits failed out of a total of 27.\n",
            "The score on these train-test partitions for these parameters will be set to nan.\n",
            "If these failures are not expected, you can try to debug them by setting error_score='raise'.\n",
            "\n",
            "Below are more details about the failures:\n",
            "--------------------------------------------------------------------------------\n",
            "1 fits failed with the following error:\n",
            "Traceback (most recent call last):\n",
            "  File \"/usr/local/lib/python3.8/dist-packages/sklearn/model_selection/_validation.py\", line 680, in _fit_and_score\n",
            "    estimator.fit(X_train, y_train, **fit_params)\n",
            "  File \"/usr/local/lib/python3.8/dist-packages/keras/wrappers/scikit_learn.py\", line 175, in fit\n",
            "    history = self.model.fit(x, y, **fit_args)\n",
            "  File \"/usr/local/lib/python3.8/dist-packages/keras/utils/traceback_utils.py\", line 70, in error_handler\n",
            "    raise e.with_traceback(filtered_tb) from None\n",
            "  File \"/tmp/__autograph_generated_fileobssof2n.py\", line 15, in tf__train_function\n",
            "    retval_ = ag__.converted_call(ag__.ld(step_function), (ag__.ld(self), ag__.ld(iterator)), None, fscope)\n",
            "ValueError: in user code:\n",
            "\n",
            "    File \"/usr/local/lib/python3.8/dist-packages/keras/engine/training.py\", line 1249, in train_function  *\n",
            "        return step_function(self, iterator)\n",
            "    File \"/usr/local/lib/python3.8/dist-packages/keras/engine/training.py\", line 1233, in step_function  **\n",
            "        outputs = model.distribute_strategy.run(run_step, args=(data,))\n",
            "    File \"/usr/local/lib/python3.8/dist-packages/keras/engine/training.py\", line 1222, in run_step  **\n",
            "        outputs = model.train_step(data)\n",
            "    File \"/usr/local/lib/python3.8/dist-packages/keras/engine/training.py\", line 1023, in train_step\n",
            "        y_pred = self(x, training=True)\n",
            "    File \"/usr/local/lib/python3.8/dist-packages/keras/utils/traceback_utils.py\", line 70, in error_handler\n",
            "        raise e.with_traceback(filtered_tb) from None\n",
            "    File \"/usr/local/lib/python3.8/dist-packages/keras/engine/input_spec.py\", line 295, in assert_input_compatibility\n",
            "        raise ValueError(\n",
            "\n",
            "    ValueError: Input 0 of layer \"sequential\" is incompatible with the layer: expected shape=(None, 5, 1), found shape=(None, 10, 1)\n",
            "\n",
            "\n",
            "--------------------------------------------------------------------------------\n",
            "1 fits failed with the following error:\n",
            "Traceback (most recent call last):\n",
            "  File \"/usr/local/lib/python3.8/dist-packages/sklearn/model_selection/_validation.py\", line 680, in _fit_and_score\n",
            "    estimator.fit(X_train, y_train, **fit_params)\n",
            "  File \"/usr/local/lib/python3.8/dist-packages/keras/wrappers/scikit_learn.py\", line 175, in fit\n",
            "    history = self.model.fit(x, y, **fit_args)\n",
            "  File \"/usr/local/lib/python3.8/dist-packages/keras/utils/traceback_utils.py\", line 70, in error_handler\n",
            "    raise e.with_traceback(filtered_tb) from None\n",
            "  File \"/tmp/__autograph_generated_file3_fi83_0.py\", line 15, in tf__train_function\n",
            "    retval_ = ag__.converted_call(ag__.ld(step_function), (ag__.ld(self), ag__.ld(iterator)), None, fscope)\n",
            "ValueError: in user code:\n",
            "\n",
            "    File \"/usr/local/lib/python3.8/dist-packages/keras/engine/training.py\", line 1249, in train_function  *\n",
            "        return step_function(self, iterator)\n",
            "    File \"/usr/local/lib/python3.8/dist-packages/keras/engine/training.py\", line 1233, in step_function  **\n",
            "        outputs = model.distribute_strategy.run(run_step, args=(data,))\n",
            "    File \"/usr/local/lib/python3.8/dist-packages/keras/engine/training.py\", line 1222, in run_step  **\n",
            "        outputs = model.train_step(data)\n",
            "    File \"/usr/local/lib/python3.8/dist-packages/keras/engine/training.py\", line 1023, in train_step\n",
            "        y_pred = self(x, training=True)\n",
            "    File \"/usr/local/lib/python3.8/dist-packages/keras/utils/traceback_utils.py\", line 70, in error_handler\n",
            "        raise e.with_traceback(filtered_tb) from None\n",
            "    File \"/usr/local/lib/python3.8/dist-packages/keras/engine/input_spec.py\", line 295, in assert_input_compatibility\n",
            "        raise ValueError(\n",
            "\n",
            "    ValueError: Input 0 of layer \"sequential\" is incompatible with the layer: expected shape=(None, 5, 1), found shape=(None, 10, 1)\n",
            "\n",
            "\n",
            "--------------------------------------------------------------------------------\n",
            "1 fits failed with the following error:\n",
            "Traceback (most recent call last):\n",
            "  File \"/usr/local/lib/python3.8/dist-packages/sklearn/model_selection/_validation.py\", line 680, in _fit_and_score\n",
            "    estimator.fit(X_train, y_train, **fit_params)\n",
            "  File \"/usr/local/lib/python3.8/dist-packages/keras/wrappers/scikit_learn.py\", line 175, in fit\n",
            "    history = self.model.fit(x, y, **fit_args)\n",
            "  File \"/usr/local/lib/python3.8/dist-packages/keras/utils/traceback_utils.py\", line 70, in error_handler\n",
            "    raise e.with_traceback(filtered_tb) from None\n",
            "  File \"/tmp/__autograph_generated_file3_fi83_0.py\", line 15, in tf__train_function\n",
            "    retval_ = ag__.converted_call(ag__.ld(step_function), (ag__.ld(self), ag__.ld(iterator)), None, fscope)\n",
            "ValueError: in user code:\n",
            "\n",
            "    File \"/usr/local/lib/python3.8/dist-packages/keras/engine/training.py\", line 1249, in train_function  *\n",
            "        return step_function(self, iterator)\n",
            "    File \"/usr/local/lib/python3.8/dist-packages/keras/engine/training.py\", line 1233, in step_function  **\n",
            "        outputs = model.distribute_strategy.run(run_step, args=(data,))\n",
            "    File \"/usr/local/lib/python3.8/dist-packages/keras/engine/training.py\", line 1222, in run_step  **\n",
            "        outputs = model.train_step(data)\n",
            "    File \"/usr/local/lib/python3.8/dist-packages/keras/engine/training.py\", line 1023, in train_step\n",
            "        y_pred = self(x, training=True)\n",
            "    File \"/usr/local/lib/python3.8/dist-packages/keras/utils/traceback_utils.py\", line 70, in error_handler\n",
            "        raise e.with_traceback(filtered_tb) from None\n",
            "    File \"/usr/local/lib/python3.8/dist-packages/keras/engine/input_spec.py\", line 295, in assert_input_compatibility\n",
            "        raise ValueError(\n",
            "\n",
            "    ValueError: Input 0 of layer \"sequential_1\" is incompatible with the layer: expected shape=(None, 5, 1), found shape=(None, 10, 1)\n",
            "\n",
            "\n",
            "--------------------------------------------------------------------------------\n",
            "1 fits failed with the following error:\n",
            "Traceback (most recent call last):\n",
            "  File \"/usr/local/lib/python3.8/dist-packages/sklearn/model_selection/_validation.py\", line 680, in _fit_and_score\n",
            "    estimator.fit(X_train, y_train, **fit_params)\n",
            "  File \"/usr/local/lib/python3.8/dist-packages/keras/wrappers/scikit_learn.py\", line 175, in fit\n",
            "    history = self.model.fit(x, y, **fit_args)\n",
            "  File \"/usr/local/lib/python3.8/dist-packages/keras/utils/traceback_utils.py\", line 70, in error_handler\n",
            "    raise e.with_traceback(filtered_tb) from None\n",
            "  File \"/tmp/__autograph_generated_file3_fi83_0.py\", line 15, in tf__train_function\n",
            "    retval_ = ag__.converted_call(ag__.ld(step_function), (ag__.ld(self), ag__.ld(iterator)), None, fscope)\n",
            "ValueError: in user code:\n",
            "\n",
            "    File \"/usr/local/lib/python3.8/dist-packages/keras/engine/training.py\", line 1249, in train_function  *\n",
            "        return step_function(self, iterator)\n",
            "    File \"/usr/local/lib/python3.8/dist-packages/keras/engine/training.py\", line 1233, in step_function  **\n",
            "        outputs = model.distribute_strategy.run(run_step, args=(data,))\n",
            "    File \"/usr/local/lib/python3.8/dist-packages/keras/engine/training.py\", line 1222, in run_step  **\n",
            "        outputs = model.train_step(data)\n",
            "    File \"/usr/local/lib/python3.8/dist-packages/keras/engine/training.py\", line 1023, in train_step\n",
            "        y_pred = self(x, training=True)\n",
            "    File \"/usr/local/lib/python3.8/dist-packages/keras/utils/traceback_utils.py\", line 70, in error_handler\n",
            "        raise e.with_traceback(filtered_tb) from None\n",
            "    File \"/usr/local/lib/python3.8/dist-packages/keras/engine/input_spec.py\", line 295, in assert_input_compatibility\n",
            "        raise ValueError(\n",
            "\n",
            "    ValueError: Input 0 of layer \"sequential_3\" is incompatible with the layer: expected shape=(None, 20, 1), found shape=(None, 10, 1)\n",
            "\n",
            "\n",
            "--------------------------------------------------------------------------------\n",
            "1 fits failed with the following error:\n",
            "Traceback (most recent call last):\n",
            "  File \"/usr/local/lib/python3.8/dist-packages/sklearn/model_selection/_validation.py\", line 680, in _fit_and_score\n",
            "    estimator.fit(X_train, y_train, **fit_params)\n",
            "  File \"/usr/local/lib/python3.8/dist-packages/keras/wrappers/scikit_learn.py\", line 175, in fit\n",
            "    history = self.model.fit(x, y, **fit_args)\n",
            "  File \"/usr/local/lib/python3.8/dist-packages/keras/utils/traceback_utils.py\", line 70, in error_handler\n",
            "    raise e.with_traceback(filtered_tb) from None\n",
            "  File \"/tmp/__autograph_generated_file3_fi83_0.py\", line 15, in tf__train_function\n",
            "    retval_ = ag__.converted_call(ag__.ld(step_function), (ag__.ld(self), ag__.ld(iterator)), None, fscope)\n",
            "ValueError: in user code:\n",
            "\n",
            "    File \"/usr/local/lib/python3.8/dist-packages/keras/engine/training.py\", line 1249, in train_function  *\n",
            "        return step_function(self, iterator)\n",
            "    File \"/usr/local/lib/python3.8/dist-packages/keras/engine/training.py\", line 1233, in step_function  **\n",
            "        outputs = model.distribute_strategy.run(run_step, args=(data,))\n",
            "    File \"/usr/local/lib/python3.8/dist-packages/keras/engine/training.py\", line 1222, in run_step  **\n",
            "        outputs = model.train_step(data)\n",
            "    File \"/usr/local/lib/python3.8/dist-packages/keras/engine/training.py\", line 1023, in train_step\n",
            "        y_pred = self(x, training=True)\n",
            "    File \"/usr/local/lib/python3.8/dist-packages/keras/utils/traceback_utils.py\", line 70, in error_handler\n",
            "        raise e.with_traceback(filtered_tb) from None\n",
            "    File \"/usr/local/lib/python3.8/dist-packages/keras/engine/input_spec.py\", line 295, in assert_input_compatibility\n",
            "        raise ValueError(\n",
            "\n",
            "    ValueError: Input 0 of layer \"sequential_4\" is incompatible with the layer: expected shape=(None, 20, 1), found shape=(None, 10, 1)\n",
            "\n",
            "\n",
            "--------------------------------------------------------------------------------\n",
            "1 fits failed with the following error:\n",
            "Traceback (most recent call last):\n",
            "  File \"/usr/local/lib/python3.8/dist-packages/sklearn/model_selection/_validation.py\", line 680, in _fit_and_score\n",
            "    estimator.fit(X_train, y_train, **fit_params)\n",
            "  File \"/usr/local/lib/python3.8/dist-packages/keras/wrappers/scikit_learn.py\", line 175, in fit\n",
            "    history = self.model.fit(x, y, **fit_args)\n",
            "  File \"/usr/local/lib/python3.8/dist-packages/keras/utils/traceback_utils.py\", line 70, in error_handler\n",
            "    raise e.with_traceback(filtered_tb) from None\n",
            "  File \"/tmp/__autograph_generated_file3_fi83_0.py\", line 15, in tf__train_function\n",
            "    retval_ = ag__.converted_call(ag__.ld(step_function), (ag__.ld(self), ag__.ld(iterator)), None, fscope)\n",
            "ValueError: in user code:\n",
            "\n",
            "    File \"/usr/local/lib/python3.8/dist-packages/keras/engine/training.py\", line 1249, in train_function  *\n",
            "        return step_function(self, iterator)\n",
            "    File \"/usr/local/lib/python3.8/dist-packages/keras/engine/training.py\", line 1233, in step_function  **\n",
            "        outputs = model.distribute_strategy.run(run_step, args=(data,))\n",
            "    File \"/usr/local/lib/python3.8/dist-packages/keras/engine/training.py\", line 1222, in run_step  **\n",
            "        outputs = model.train_step(data)\n",
            "    File \"/usr/local/lib/python3.8/dist-packages/keras/engine/training.py\", line 1023, in train_step\n",
            "        y_pred = self(x, training=True)\n",
            "    File \"/usr/local/lib/python3.8/dist-packages/keras/utils/traceback_utils.py\", line 70, in error_handler\n",
            "        raise e.with_traceback(filtered_tb) from None\n",
            "    File \"/usr/local/lib/python3.8/dist-packages/keras/engine/input_spec.py\", line 295, in assert_input_compatibility\n",
            "        raise ValueError(\n",
            "\n",
            "    ValueError: Input 0 of layer \"sequential_5\" is incompatible with the layer: expected shape=(None, 20, 1), found shape=(None, 10, 1)\n",
            "\n",
            "\n",
            "--------------------------------------------------------------------------------\n",
            "1 fits failed with the following error:\n",
            "Traceback (most recent call last):\n",
            "  File \"/usr/local/lib/python3.8/dist-packages/sklearn/model_selection/_validation.py\", line 680, in _fit_and_score\n",
            "    estimator.fit(X_train, y_train, **fit_params)\n",
            "  File \"/usr/local/lib/python3.8/dist-packages/keras/wrappers/scikit_learn.py\", line 175, in fit\n",
            "    history = self.model.fit(x, y, **fit_args)\n",
            "  File \"/usr/local/lib/python3.8/dist-packages/keras/utils/traceback_utils.py\", line 70, in error_handler\n",
            "    raise e.with_traceback(filtered_tb) from None\n",
            "  File \"/tmp/__autograph_generated_file3_fi83_0.py\", line 15, in tf__train_function\n",
            "    retval_ = ag__.converted_call(ag__.ld(step_function), (ag__.ld(self), ag__.ld(iterator)), None, fscope)\n",
            "ValueError: in user code:\n",
            "\n",
            "    File \"/usr/local/lib/python3.8/dist-packages/keras/engine/training.py\", line 1249, in train_function  *\n",
            "        return step_function(self, iterator)\n",
            "    File \"/usr/local/lib/python3.8/dist-packages/keras/engine/training.py\", line 1233, in step_function  **\n",
            "        outputs = model.distribute_strategy.run(run_step, args=(data,))\n",
            "    File \"/usr/local/lib/python3.8/dist-packages/keras/engine/training.py\", line 1222, in run_step  **\n",
            "        outputs = model.train_step(data)\n",
            "    File \"/usr/local/lib/python3.8/dist-packages/keras/engine/training.py\", line 1023, in train_step\n",
            "        y_pred = self(x, training=True)\n",
            "    File \"/usr/local/lib/python3.8/dist-packages/keras/utils/traceback_utils.py\", line 70, in error_handler\n",
            "        raise e.with_traceback(filtered_tb) from None\n",
            "    File \"/usr/local/lib/python3.8/dist-packages/keras/engine/input_spec.py\", line 295, in assert_input_compatibility\n",
            "        raise ValueError(\n",
            "\n",
            "    ValueError: Input 0 of layer \"sequential_6\" is incompatible with the layer: expected shape=(None, 5, 1), found shape=(None, 10, 1)\n",
            "\n",
            "\n",
            "--------------------------------------------------------------------------------\n",
            "1 fits failed with the following error:\n",
            "Traceback (most recent call last):\n",
            "  File \"/usr/local/lib/python3.8/dist-packages/sklearn/model_selection/_validation.py\", line 680, in _fit_and_score\n",
            "    estimator.fit(X_train, y_train, **fit_params)\n",
            "  File \"/usr/local/lib/python3.8/dist-packages/keras/wrappers/scikit_learn.py\", line 175, in fit\n",
            "    history = self.model.fit(x, y, **fit_args)\n",
            "  File \"/usr/local/lib/python3.8/dist-packages/keras/utils/traceback_utils.py\", line 70, in error_handler\n",
            "    raise e.with_traceback(filtered_tb) from None\n",
            "  File \"/tmp/__autograph_generated_file3_fi83_0.py\", line 15, in tf__train_function\n",
            "    retval_ = ag__.converted_call(ag__.ld(step_function), (ag__.ld(self), ag__.ld(iterator)), None, fscope)\n",
            "ValueError: in user code:\n",
            "\n",
            "    File \"/usr/local/lib/python3.8/dist-packages/keras/engine/training.py\", line 1249, in train_function  *\n",
            "        return step_function(self, iterator)\n",
            "    File \"/usr/local/lib/python3.8/dist-packages/keras/engine/training.py\", line 1233, in step_function  **\n",
            "        outputs = model.distribute_strategy.run(run_step, args=(data,))\n",
            "    File \"/usr/local/lib/python3.8/dist-packages/keras/engine/training.py\", line 1222, in run_step  **\n",
            "        outputs = model.train_step(data)\n",
            "    File \"/usr/local/lib/python3.8/dist-packages/keras/engine/training.py\", line 1023, in train_step\n",
            "        y_pred = self(x, training=True)\n",
            "    File \"/usr/local/lib/python3.8/dist-packages/keras/utils/traceback_utils.py\", line 70, in error_handler\n",
            "        raise e.with_traceback(filtered_tb) from None\n",
            "    File \"/usr/local/lib/python3.8/dist-packages/keras/engine/input_spec.py\", line 295, in assert_input_compatibility\n",
            "        raise ValueError(\n",
            "\n",
            "    ValueError: Input 0 of layer \"sequential_7\" is incompatible with the layer: expected shape=(None, 5, 1), found shape=(None, 10, 1)\n",
            "\n",
            "\n",
            "--------------------------------------------------------------------------------\n",
            "1 fits failed with the following error:\n",
            "Traceback (most recent call last):\n",
            "  File \"/usr/local/lib/python3.8/dist-packages/sklearn/model_selection/_validation.py\", line 680, in _fit_and_score\n",
            "    estimator.fit(X_train, y_train, **fit_params)\n",
            "  File \"/usr/local/lib/python3.8/dist-packages/keras/wrappers/scikit_learn.py\", line 175, in fit\n",
            "    history = self.model.fit(x, y, **fit_args)\n",
            "  File \"/usr/local/lib/python3.8/dist-packages/keras/utils/traceback_utils.py\", line 70, in error_handler\n",
            "    raise e.with_traceback(filtered_tb) from None\n",
            "  File \"/tmp/__autograph_generated_file3_fi83_0.py\", line 15, in tf__train_function\n",
            "    retval_ = ag__.converted_call(ag__.ld(step_function), (ag__.ld(self), ag__.ld(iterator)), None, fscope)\n",
            "ValueError: in user code:\n",
            "\n",
            "    File \"/usr/local/lib/python3.8/dist-packages/keras/engine/training.py\", line 1249, in train_function  *\n",
            "        return step_function(self, iterator)\n",
            "    File \"/usr/local/lib/python3.8/dist-packages/keras/engine/training.py\", line 1233, in step_function  **\n",
            "        outputs = model.distribute_strategy.run(run_step, args=(data,))\n",
            "    File \"/usr/local/lib/python3.8/dist-packages/keras/engine/training.py\", line 1222, in run_step  **\n",
            "        outputs = model.train_step(data)\n",
            "    File \"/usr/local/lib/python3.8/dist-packages/keras/engine/training.py\", line 1023, in train_step\n",
            "        y_pred = self(x, training=True)\n",
            "    File \"/usr/local/lib/python3.8/dist-packages/keras/utils/traceback_utils.py\", line 70, in error_handler\n",
            "        raise e.with_traceback(filtered_tb) from None\n",
            "    File \"/usr/local/lib/python3.8/dist-packages/keras/engine/input_spec.py\", line 295, in assert_input_compatibility\n",
            "        raise ValueError(\n",
            "\n",
            "    ValueError: Input 0 of layer \"sequential_8\" is incompatible with the layer: expected shape=(None, 5, 1), found shape=(None, 10, 1)\n",
            "\n",
            "\n",
            "--------------------------------------------------------------------------------\n",
            "1 fits failed with the following error:\n",
            "Traceback (most recent call last):\n",
            "  File \"/usr/local/lib/python3.8/dist-packages/sklearn/model_selection/_validation.py\", line 680, in _fit_and_score\n",
            "    estimator.fit(X_train, y_train, **fit_params)\n",
            "  File \"/usr/local/lib/python3.8/dist-packages/keras/wrappers/scikit_learn.py\", line 175, in fit\n",
            "    history = self.model.fit(x, y, **fit_args)\n",
            "  File \"/usr/local/lib/python3.8/dist-packages/keras/utils/traceback_utils.py\", line 70, in error_handler\n",
            "    raise e.with_traceback(filtered_tb) from None\n",
            "  File \"/tmp/__autograph_generated_file3_fi83_0.py\", line 15, in tf__train_function\n",
            "    retval_ = ag__.converted_call(ag__.ld(step_function), (ag__.ld(self), ag__.ld(iterator)), None, fscope)\n",
            "ValueError: in user code:\n",
            "\n",
            "    File \"/usr/local/lib/python3.8/dist-packages/keras/engine/training.py\", line 1249, in train_function  *\n",
            "        return step_function(self, iterator)\n",
            "    File \"/usr/local/lib/python3.8/dist-packages/keras/engine/training.py\", line 1233, in step_function  **\n",
            "        outputs = model.distribute_strategy.run(run_step, args=(data,))\n",
            "    File \"/usr/local/lib/python3.8/dist-packages/keras/engine/training.py\", line 1222, in run_step  **\n",
            "        outputs = model.train_step(data)\n",
            "    File \"/usr/local/lib/python3.8/dist-packages/keras/engine/training.py\", line 1023, in train_step\n",
            "        y_pred = self(x, training=True)\n",
            "    File \"/usr/local/lib/python3.8/dist-packages/keras/utils/traceback_utils.py\", line 70, in error_handler\n",
            "        raise e.with_traceback(filtered_tb) from None\n",
            "    File \"/usr/local/lib/python3.8/dist-packages/keras/engine/input_spec.py\", line 295, in assert_input_compatibility\n",
            "        raise ValueError(\n",
            "\n",
            "    ValueError: Input 0 of layer \"sequential_11\" is incompatible with the layer: expected shape=(None, 20, 1), found shape=(None, 10, 1)\n",
            "\n",
            "\n",
            "--------------------------------------------------------------------------------\n",
            "1 fits failed with the following error:\n",
            "Traceback (most recent call last):\n",
            "  File \"/usr/local/lib/python3.8/dist-packages/sklearn/model_selection/_validation.py\", line 680, in _fit_and_score\n",
            "    estimator.fit(X_train, y_train, **fit_params)\n",
            "  File \"/usr/local/lib/python3.8/dist-packages/keras/wrappers/scikit_learn.py\", line 175, in fit\n",
            "    history = self.model.fit(x, y, **fit_args)\n",
            "  File \"/usr/local/lib/python3.8/dist-packages/keras/utils/traceback_utils.py\", line 70, in error_handler\n",
            "    raise e.with_traceback(filtered_tb) from None\n",
            "  File \"/tmp/__autograph_generated_file3_fi83_0.py\", line 15, in tf__train_function\n",
            "    retval_ = ag__.converted_call(ag__.ld(step_function), (ag__.ld(self), ag__.ld(iterator)), None, fscope)\n",
            "ValueError: in user code:\n",
            "\n",
            "    File \"/usr/local/lib/python3.8/dist-packages/keras/engine/training.py\", line 1249, in train_function  *\n",
            "        return step_function(self, iterator)\n",
            "    File \"/usr/local/lib/python3.8/dist-packages/keras/engine/training.py\", line 1233, in step_function  **\n",
            "        outputs = model.distribute_strategy.run(run_step, args=(data,))\n",
            "    File \"/usr/local/lib/python3.8/dist-packages/keras/engine/training.py\", line 1222, in run_step  **\n",
            "        outputs = model.train_step(data)\n",
            "    File \"/usr/local/lib/python3.8/dist-packages/keras/engine/training.py\", line 1023, in train_step\n",
            "        y_pred = self(x, training=True)\n",
            "    File \"/usr/local/lib/python3.8/dist-packages/keras/utils/traceback_utils.py\", line 70, in error_handler\n",
            "        raise e.with_traceback(filtered_tb) from None\n",
            "    File \"/usr/local/lib/python3.8/dist-packages/keras/engine/input_spec.py\", line 295, in assert_input_compatibility\n",
            "        raise ValueError(\n",
            "\n",
            "    ValueError: Input 0 of layer \"sequential_12\" is incompatible with the layer: expected shape=(None, 20, 1), found shape=(None, 10, 1)\n",
            "\n",
            "\n",
            "--------------------------------------------------------------------------------\n",
            "1 fits failed with the following error:\n",
            "Traceback (most recent call last):\n",
            "  File \"/usr/local/lib/python3.8/dist-packages/sklearn/model_selection/_validation.py\", line 680, in _fit_and_score\n",
            "    estimator.fit(X_train, y_train, **fit_params)\n",
            "  File \"/usr/local/lib/python3.8/dist-packages/keras/wrappers/scikit_learn.py\", line 175, in fit\n",
            "    history = self.model.fit(x, y, **fit_args)\n",
            "  File \"/usr/local/lib/python3.8/dist-packages/keras/utils/traceback_utils.py\", line 70, in error_handler\n",
            "    raise e.with_traceback(filtered_tb) from None\n",
            "  File \"/tmp/__autograph_generated_fileobssof2n.py\", line 15, in tf__train_function\n",
            "    retval_ = ag__.converted_call(ag__.ld(step_function), (ag__.ld(self), ag__.ld(iterator)), None, fscope)\n",
            "ValueError: in user code:\n",
            "\n",
            "    File \"/usr/local/lib/python3.8/dist-packages/keras/engine/training.py\", line 1249, in train_function  *\n",
            "        return step_function(self, iterator)\n",
            "    File \"/usr/local/lib/python3.8/dist-packages/keras/engine/training.py\", line 1233, in step_function  **\n",
            "        outputs = model.distribute_strategy.run(run_step, args=(data,))\n",
            "    File \"/usr/local/lib/python3.8/dist-packages/keras/engine/training.py\", line 1222, in run_step  **\n",
            "        outputs = model.train_step(data)\n",
            "    File \"/usr/local/lib/python3.8/dist-packages/keras/engine/training.py\", line 1023, in train_step\n",
            "        y_pred = self(x, training=True)\n",
            "    File \"/usr/local/lib/python3.8/dist-packages/keras/utils/traceback_utils.py\", line 70, in error_handler\n",
            "        raise e.with_traceback(filtered_tb) from None\n",
            "    File \"/usr/local/lib/python3.8/dist-packages/keras/engine/input_spec.py\", line 295, in assert_input_compatibility\n",
            "        raise ValueError(\n",
            "\n",
            "    ValueError: Input 0 of layer \"sequential_4\" is incompatible with the layer: expected shape=(None, 20, 1), found shape=(None, 10, 1)\n",
            "\n",
            "\n",
            "--------------------------------------------------------------------------------\n",
            "1 fits failed with the following error:\n",
            "Traceback (most recent call last):\n",
            "  File \"/usr/local/lib/python3.8/dist-packages/sklearn/model_selection/_validation.py\", line 680, in _fit_and_score\n",
            "    estimator.fit(X_train, y_train, **fit_params)\n",
            "  File \"/usr/local/lib/python3.8/dist-packages/keras/wrappers/scikit_learn.py\", line 175, in fit\n",
            "    history = self.model.fit(x, y, **fit_args)\n",
            "  File \"/usr/local/lib/python3.8/dist-packages/keras/utils/traceback_utils.py\", line 70, in error_handler\n",
            "    raise e.with_traceback(filtered_tb) from None\n",
            "  File \"/tmp/__autograph_generated_file3_fi83_0.py\", line 15, in tf__train_function\n",
            "    retval_ = ag__.converted_call(ag__.ld(step_function), (ag__.ld(self), ag__.ld(iterator)), None, fscope)\n",
            "ValueError: in user code:\n",
            "\n",
            "    File \"/usr/local/lib/python3.8/dist-packages/keras/engine/training.py\", line 1249, in train_function  *\n",
            "        return step_function(self, iterator)\n",
            "    File \"/usr/local/lib/python3.8/dist-packages/keras/engine/training.py\", line 1233, in step_function  **\n",
            "        outputs = model.distribute_strategy.run(run_step, args=(data,))\n",
            "    File \"/usr/local/lib/python3.8/dist-packages/keras/engine/training.py\", line 1222, in run_step  **\n",
            "        outputs = model.train_step(data)\n",
            "    File \"/usr/local/lib/python3.8/dist-packages/keras/engine/training.py\", line 1023, in train_step\n",
            "        y_pred = self(x, training=True)\n",
            "    File \"/usr/local/lib/python3.8/dist-packages/keras/utils/traceback_utils.py\", line 70, in error_handler\n",
            "        raise e.with_traceback(filtered_tb) from None\n",
            "    File \"/usr/local/lib/python3.8/dist-packages/keras/engine/input_spec.py\", line 295, in assert_input_compatibility\n",
            "        raise ValueError(\n",
            "\n",
            "    ValueError: Input 0 of layer \"sequential_13\" is incompatible with the layer: expected shape=(None, 5, 1), found shape=(None, 10, 1)\n",
            "\n",
            "\n",
            "--------------------------------------------------------------------------------\n",
            "1 fits failed with the following error:\n",
            "Traceback (most recent call last):\n",
            "  File \"/usr/local/lib/python3.8/dist-packages/sklearn/model_selection/_validation.py\", line 680, in _fit_and_score\n",
            "    estimator.fit(X_train, y_train, **fit_params)\n",
            "  File \"/usr/local/lib/python3.8/dist-packages/keras/wrappers/scikit_learn.py\", line 175, in fit\n",
            "    history = self.model.fit(x, y, **fit_args)\n",
            "  File \"/usr/local/lib/python3.8/dist-packages/keras/utils/traceback_utils.py\", line 70, in error_handler\n",
            "    raise e.with_traceback(filtered_tb) from None\n",
            "  File \"/tmp/__autograph_generated_file3_fi83_0.py\", line 15, in tf__train_function\n",
            "    retval_ = ag__.converted_call(ag__.ld(step_function), (ag__.ld(self), ag__.ld(iterator)), None, fscope)\n",
            "ValueError: in user code:\n",
            "\n",
            "    File \"/usr/local/lib/python3.8/dist-packages/keras/engine/training.py\", line 1249, in train_function  *\n",
            "        return step_function(self, iterator)\n",
            "    File \"/usr/local/lib/python3.8/dist-packages/keras/engine/training.py\", line 1233, in step_function  **\n",
            "        outputs = model.distribute_strategy.run(run_step, args=(data,))\n",
            "    File \"/usr/local/lib/python3.8/dist-packages/keras/engine/training.py\", line 1222, in run_step  **\n",
            "        outputs = model.train_step(data)\n",
            "    File \"/usr/local/lib/python3.8/dist-packages/keras/engine/training.py\", line 1023, in train_step\n",
            "        y_pred = self(x, training=True)\n",
            "    File \"/usr/local/lib/python3.8/dist-packages/keras/utils/traceback_utils.py\", line 70, in error_handler\n",
            "        raise e.with_traceback(filtered_tb) from None\n",
            "    File \"/usr/local/lib/python3.8/dist-packages/keras/engine/input_spec.py\", line 295, in assert_input_compatibility\n",
            "        raise ValueError(\n",
            "\n",
            "    ValueError: Input 0 of layer \"sequential_14\" is incompatible with the layer: expected shape=(None, 5, 1), found shape=(None, 10, 1)\n",
            "\n",
            "\n",
            "--------------------------------------------------------------------------------\n",
            "1 fits failed with the following error:\n",
            "Traceback (most recent call last):\n",
            "  File \"/usr/local/lib/python3.8/dist-packages/sklearn/model_selection/_validation.py\", line 680, in _fit_and_score\n",
            "    estimator.fit(X_train, y_train, **fit_params)\n",
            "  File \"/usr/local/lib/python3.8/dist-packages/keras/wrappers/scikit_learn.py\", line 175, in fit\n",
            "    history = self.model.fit(x, y, **fit_args)\n",
            "  File \"/usr/local/lib/python3.8/dist-packages/keras/utils/traceback_utils.py\", line 70, in error_handler\n",
            "    raise e.with_traceback(filtered_tb) from None\n",
            "  File \"/tmp/__autograph_generated_fileobssof2n.py\", line 15, in tf__train_function\n",
            "    retval_ = ag__.converted_call(ag__.ld(step_function), (ag__.ld(self), ag__.ld(iterator)), None, fscope)\n",
            "ValueError: in user code:\n",
            "\n",
            "    File \"/usr/local/lib/python3.8/dist-packages/keras/engine/training.py\", line 1249, in train_function  *\n",
            "        return step_function(self, iterator)\n",
            "    File \"/usr/local/lib/python3.8/dist-packages/keras/engine/training.py\", line 1233, in step_function  **\n",
            "        outputs = model.distribute_strategy.run(run_step, args=(data,))\n",
            "    File \"/usr/local/lib/python3.8/dist-packages/keras/engine/training.py\", line 1222, in run_step  **\n",
            "        outputs = model.train_step(data)\n",
            "    File \"/usr/local/lib/python3.8/dist-packages/keras/engine/training.py\", line 1023, in train_step\n",
            "        y_pred = self(x, training=True)\n",
            "    File \"/usr/local/lib/python3.8/dist-packages/keras/utils/traceback_utils.py\", line 70, in error_handler\n",
            "        raise e.with_traceback(filtered_tb) from None\n",
            "    File \"/usr/local/lib/python3.8/dist-packages/keras/engine/input_spec.py\", line 295, in assert_input_compatibility\n",
            "        raise ValueError(\n",
            "\n",
            "    ValueError: Input 0 of layer \"sequential_5\" is incompatible with the layer: expected shape=(None, 5, 1), found shape=(None, 10, 1)\n",
            "\n",
            "\n",
            "--------------------------------------------------------------------------------\n",
            "1 fits failed with the following error:\n",
            "Traceback (most recent call last):\n",
            "  File \"/usr/local/lib/python3.8/dist-packages/sklearn/model_selection/_validation.py\", line 680, in _fit_and_score\n",
            "    estimator.fit(X_train, y_train, **fit_params)\n",
            "  File \"/usr/local/lib/python3.8/dist-packages/keras/wrappers/scikit_learn.py\", line 175, in fit\n",
            "    history = self.model.fit(x, y, **fit_args)\n",
            "  File \"/usr/local/lib/python3.8/dist-packages/keras/utils/traceback_utils.py\", line 70, in error_handler\n",
            "    raise e.with_traceback(filtered_tb) from None\n",
            "  File \"/tmp/__autograph_generated_file3_fi83_0.py\", line 15, in tf__train_function\n",
            "    retval_ = ag__.converted_call(ag__.ld(step_function), (ag__.ld(self), ag__.ld(iterator)), None, fscope)\n",
            "ValueError: in user code:\n",
            "\n",
            "    File \"/usr/local/lib/python3.8/dist-packages/keras/engine/training.py\", line 1249, in train_function  *\n",
            "        return step_function(self, iterator)\n",
            "    File \"/usr/local/lib/python3.8/dist-packages/keras/engine/training.py\", line 1233, in step_function  **\n",
            "        outputs = model.distribute_strategy.run(run_step, args=(data,))\n",
            "    File \"/usr/local/lib/python3.8/dist-packages/keras/engine/training.py\", line 1222, in run_step  **\n",
            "        outputs = model.train_step(data)\n",
            "    File \"/usr/local/lib/python3.8/dist-packages/keras/engine/training.py\", line 1023, in train_step\n",
            "        y_pred = self(x, training=True)\n",
            "    File \"/usr/local/lib/python3.8/dist-packages/keras/utils/traceback_utils.py\", line 70, in error_handler\n",
            "        raise e.with_traceback(filtered_tb) from None\n",
            "    File \"/usr/local/lib/python3.8/dist-packages/keras/engine/input_spec.py\", line 295, in assert_input_compatibility\n",
            "        raise ValueError(\n",
            "\n",
            "    ValueError: Input 0 of layer \"sequential_16\" is incompatible with the layer: expected shape=(None, 20, 1), found shape=(None, 10, 1)\n",
            "\n",
            "\n",
            "--------------------------------------------------------------------------------\n",
            "1 fits failed with the following error:\n",
            "Traceback (most recent call last):\n",
            "  File \"/usr/local/lib/python3.8/dist-packages/sklearn/model_selection/_validation.py\", line 680, in _fit_and_score\n",
            "    estimator.fit(X_train, y_train, **fit_params)\n",
            "  File \"/usr/local/lib/python3.8/dist-packages/keras/wrappers/scikit_learn.py\", line 175, in fit\n",
            "    history = self.model.fit(x, y, **fit_args)\n",
            "  File \"/usr/local/lib/python3.8/dist-packages/keras/utils/traceback_utils.py\", line 70, in error_handler\n",
            "    raise e.with_traceback(filtered_tb) from None\n",
            "  File \"/tmp/__autograph_generated_file3_fi83_0.py\", line 15, in tf__train_function\n",
            "    retval_ = ag__.converted_call(ag__.ld(step_function), (ag__.ld(self), ag__.ld(iterator)), None, fscope)\n",
            "ValueError: in user code:\n",
            "\n",
            "    File \"/usr/local/lib/python3.8/dist-packages/keras/engine/training.py\", line 1249, in train_function  *\n",
            "        return step_function(self, iterator)\n",
            "    File \"/usr/local/lib/python3.8/dist-packages/keras/engine/training.py\", line 1233, in step_function  **\n",
            "        outputs = model.distribute_strategy.run(run_step, args=(data,))\n",
            "    File \"/usr/local/lib/python3.8/dist-packages/keras/engine/training.py\", line 1222, in run_step  **\n",
            "        outputs = model.train_step(data)\n",
            "    File \"/usr/local/lib/python3.8/dist-packages/keras/engine/training.py\", line 1023, in train_step\n",
            "        y_pred = self(x, training=True)\n",
            "    File \"/usr/local/lib/python3.8/dist-packages/keras/utils/traceback_utils.py\", line 70, in error_handler\n",
            "        raise e.with_traceback(filtered_tb) from None\n",
            "    File \"/usr/local/lib/python3.8/dist-packages/keras/engine/input_spec.py\", line 295, in assert_input_compatibility\n",
            "        raise ValueError(\n",
            "\n",
            "    ValueError: Input 0 of layer \"sequential_17\" is incompatible with the layer: expected shape=(None, 20, 1), found shape=(None, 10, 1)\n",
            "\n",
            "\n",
            "--------------------------------------------------------------------------------\n",
            "1 fits failed with the following error:\n",
            "Traceback (most recent call last):\n",
            "  File \"/usr/local/lib/python3.8/dist-packages/sklearn/model_selection/_validation.py\", line 680, in _fit_and_score\n",
            "    estimator.fit(X_train, y_train, **fit_params)\n",
            "  File \"/usr/local/lib/python3.8/dist-packages/keras/wrappers/scikit_learn.py\", line 175, in fit\n",
            "    history = self.model.fit(x, y, **fit_args)\n",
            "  File \"/usr/local/lib/python3.8/dist-packages/keras/utils/traceback_utils.py\", line 70, in error_handler\n",
            "    raise e.with_traceback(filtered_tb) from None\n",
            "  File \"/tmp/__autograph_generated_file3_fi83_0.py\", line 15, in tf__train_function\n",
            "    retval_ = ag__.converted_call(ag__.ld(step_function), (ag__.ld(self), ag__.ld(iterator)), None, fscope)\n",
            "ValueError: in user code:\n",
            "\n",
            "    File \"/usr/local/lib/python3.8/dist-packages/keras/engine/training.py\", line 1249, in train_function  *\n",
            "        return step_function(self, iterator)\n",
            "    File \"/usr/local/lib/python3.8/dist-packages/keras/engine/training.py\", line 1233, in step_function  **\n",
            "        outputs = model.distribute_strategy.run(run_step, args=(data,))\n",
            "    File \"/usr/local/lib/python3.8/dist-packages/keras/engine/training.py\", line 1222, in run_step  **\n",
            "        outputs = model.train_step(data)\n",
            "    File \"/usr/local/lib/python3.8/dist-packages/keras/engine/training.py\", line 1023, in train_step\n",
            "        y_pred = self(x, training=True)\n",
            "    File \"/usr/local/lib/python3.8/dist-packages/keras/utils/traceback_utils.py\", line 70, in error_handler\n",
            "        raise e.with_traceback(filtered_tb) from None\n",
            "    File \"/usr/local/lib/python3.8/dist-packages/keras/engine/input_spec.py\", line 295, in assert_input_compatibility\n",
            "        raise ValueError(\n",
            "\n",
            "    ValueError: Input 0 of layer \"sequential_18\" is incompatible with the layer: expected shape=(None, 20, 1), found shape=(None, 10, 1)\n",
            "\n",
            "\n",
            "  warnings.warn(some_fits_failed_message, FitFailedWarning)\n",
            "/usr/local/lib/python3.8/dist-packages/sklearn/model_selection/_search.py:969: UserWarning: One or more of the test scores are non-finite: [        nan -0.69332985         nan         nan -0.69430502         nan\n",
            "         nan -0.69360805         nan]\n",
            "  warnings.warn(\n"
          ]
        },
        {
          "output_type": "stream",
          "name": "stdout",
          "text": [
            "Best: -0.693330 using {'batch_size': 10, 'epochs': 1, 'lags': 10}\n"
          ]
        }
      ]
    },
    {
      "cell_type": "code",
      "source": [
        "## Best: -0.693330 using {'batch_size': 10, 'epochs': 1, 'lags': 10}"
      ],
      "metadata": {
        "id": "R7BHsTP0RF24"
      },
      "execution_count": null,
      "outputs": []
    },
    {
      "cell_type": "code",
      "source": [],
      "metadata": {
        "id": "y7mOc2pIRF75"
      },
      "execution_count": null,
      "outputs": []
    },
    {
      "cell_type": "code",
      "source": [],
      "metadata": {
        "id": "rVYrUhZjRF_V"
      },
      "execution_count": null,
      "outputs": []
    }
  ]
}
